[2023-12-15 16:18:29 +0000] [129128] [INFO] Starting gunicorn 21.2.0
[2023-12-15 16:18:29 +0000] [129128] [INFO] Listening at: http://0.0.0.0:8000 (129128)
[2023-12-15 16:18:29 +0000] [129128] [INFO] Using worker: sync
[2023-12-15 16:18:29 +0000] [129130] [INFO] Booting worker with pid: 129130
[2023-12-15 16:18:29 +0000] [129131] [INFO] Booting worker with pid: 129131
[2023-12-15 16:18:29 +0000] [129132] [INFO] Booting worker with pid: 129132
[2023-12-15 16:22:15,530] ERROR in app: Exception on /product/result [GET]
Traceback (most recent call last):
  File "/home/ec2-user/venv/lib64/python3.9/site-packages/flask/app.py", line 1455, in wsgi_app
    response = self.full_dispatch_request()
  File "/home/ec2-user/venv/lib64/python3.9/site-packages/flask/app.py", line 869, in full_dispatch_request
    rv = self.handle_user_exception(e)
  File "/home/ec2-user/venv/lib64/python3.9/site-packages/flask_cors/extension.py", line 176, in wrapped_function
    return cors_after_request(app.make_response(f(*args, **kwargs)))
  File "/home/ec2-user/venv/lib64/python3.9/site-packages/flask/app.py", line 867, in full_dispatch_request
    rv = self.dispatch_request()
  File "/home/ec2-user/venv/lib64/python3.9/site-packages/flask/app.py", line 852, in dispatch_request
    return self.ensure_sync(self.view_functions[rule.endpoint])(**view_args)
  File "/home/ec2-user/BluestPeakBackend/project/frameworks_and_drivers/controllers/product.py", line 18, in get_products
    bpproducts.logger.debug('trying to get products')
AttributeError: 'Blueprint' object has no attribute 'logger'
[2023-12-15 16:22:45,754] ERROR in app: Request finalizing failed with an error while handling an error
Traceback (most recent call last):
  File "/home/ec2-user/venv/lib64/python3.9/site-packages/flask/app.py", line 1455, in wsgi_app
    response = self.full_dispatch_request()
  File "/home/ec2-user/venv/lib64/python3.9/site-packages/flask/app.py", line 869, in full_dispatch_request
    rv = self.handle_user_exception(e)
  File "/home/ec2-user/venv/lib64/python3.9/site-packages/flask_cors/extension.py", line 176, in wrapped_function
    return cors_after_request(app.make_response(f(*args, **kwargs)))
  File "/home/ec2-user/venv/lib64/python3.9/site-packages/flask/app.py", line 867, in full_dispatch_request
    rv = self.dispatch_request()
  File "/home/ec2-user/venv/lib64/python3.9/site-packages/flask/app.py", line 852, in dispatch_request
    return self.ensure_sync(self.view_functions[rule.endpoint])(**view_args)
  File "/home/ec2-user/BluestPeakBackend/project/frameworks_and_drivers/controllers/product.py", line 18, in get_products
    bpproducts.logger.debug('trying to get products')
AttributeError: 'Blueprint' object has no attribute 'logger'

During handling of the above exception, another exception occurred:

Traceback (most recent call last):
  File "/home/ec2-user/venv/lib64/python3.9/site-packages/flask/app.py", line 891, in finalize_request
    response = self.process_response(response)
  File "/home/ec2-user/venv/lib64/python3.9/site-packages/flask/app.py", line 1267, in process_response
    response = self.ensure_sync(func)(response)
  File "/home/ec2-user/BluestPeakBackend/project/frameworks_and_drivers/app.py", line 85, in after_request
    if not EnterpriseDao.enterprise_has_paid(enterprise_id):
  File "/home/ec2-user/BluestPeakBackend/project/interface_adapters/dao/enterpriseDao.py", line 64, in enterprise_has_paid
    enterprise = enterprises.find_one({'_id':enterprise_id})
  File "/home/ec2-user/venv/lib64/python3.9/site-packages/pymongo/collection.py", line 1224, in find_one
    for result in cursor.limit(-1):
  File "/home/ec2-user/venv/lib64/python3.9/site-packages/pymongo/cursor.py", line 1176, in next
    if len(self.__data) or self._refresh():
  File "/home/ec2-user/venv/lib64/python3.9/site-packages/pymongo/cursor.py", line 1070, in _refresh
    self.__session = self.__collection.database.client._ensure_session()
  File "/home/ec2-user/venv/lib64/python3.9/site-packages/pymongo/mongo_client.py", line 1391, in _ensure_session
    return self.start_session(causal_consistency=False)
  File "/home/ec2-user/venv/lib64/python3.9/site-packages/pymongo/mongo_client.py", line 1369, in start_session
    server_session = self._get_server_session()
  File "/home/ec2-user/venv/lib64/python3.9/site-packages/pymongo/mongo_client.py", line 1377, in _get_server_session
    return self._topology.get_server_session()
  File "/home/ec2-user/venv/lib64/python3.9/site-packages/pymongo/topology.py", line 418, in get_server_session
    self._select_servers_loop(
  File "/home/ec2-user/venv/lib64/python3.9/site-packages/pymongo/topology.py", line 198, in _select_servers_loop
    raise ServerSelectionTimeoutError(
pymongo.errors.ServerSelectionTimeoutError: SSL handshake failed: [SSL: TLSV1_ALERT_INTERNAL_ERROR] tlsv1 alert internal error (_ssl.c:1129),SSL handshake failed: [SSL: TLSV1_ALERT_INTERNAL_ERROR] tlsv1 alert internal error (_ssl.c:1129),SSL handshake failed: [SSL: TLSV1_ALERT_INTERNAL_ERROR] tlsv1 alert internal error (_ssl.c:1129)
[2023-12-15 16:35:03,219] ERROR in app: Exception on /product/result [GET]
Traceback (most recent call last):
  File "/home/ec2-user/venv/lib64/python3.9/site-packages/flask/app.py", line 1455, in wsgi_app
    response = self.full_dispatch_request()
  File "/home/ec2-user/venv/lib64/python3.9/site-packages/flask/app.py", line 869, in full_dispatch_request
    rv = self.handle_user_exception(e)
  File "/home/ec2-user/venv/lib64/python3.9/site-packages/flask_cors/extension.py", line 176, in wrapped_function
    return cors_after_request(app.make_response(f(*args, **kwargs)))
  File "/home/ec2-user/venv/lib64/python3.9/site-packages/flask/app.py", line 867, in full_dispatch_request
    rv = self.dispatch_request()
  File "/home/ec2-user/venv/lib64/python3.9/site-packages/flask/app.py", line 852, in dispatch_request
    return self.ensure_sync(self.view_functions[rule.endpoint])(**view_args)
  File "/home/ec2-user/BluestPeakBackend/project/frameworks_and_drivers/controllers/product.py", line 18, in get_products
    """Returns a list with all the products from the data base."""
AttributeError: 'Blueprint' object has no attribute 'logger'
[2023-12-15 16:35:33,386] ERROR in app: Request finalizing failed with an error while handling an error
Traceback (most recent call last):
  File "/home/ec2-user/venv/lib64/python3.9/site-packages/flask/app.py", line 1455, in wsgi_app
    response = self.full_dispatch_request()
  File "/home/ec2-user/venv/lib64/python3.9/site-packages/flask/app.py", line 869, in full_dispatch_request
    rv = self.handle_user_exception(e)
  File "/home/ec2-user/venv/lib64/python3.9/site-packages/flask_cors/extension.py", line 176, in wrapped_function
    return cors_after_request(app.make_response(f(*args, **kwargs)))
  File "/home/ec2-user/venv/lib64/python3.9/site-packages/flask/app.py", line 867, in full_dispatch_request
    rv = self.dispatch_request()
  File "/home/ec2-user/venv/lib64/python3.9/site-packages/flask/app.py", line 852, in dispatch_request
    return self.ensure_sync(self.view_functions[rule.endpoint])(**view_args)
  File "/home/ec2-user/BluestPeakBackend/project/frameworks_and_drivers/controllers/product.py", line 18, in get_products
    """Returns a list with all the products from the data base."""
AttributeError: 'Blueprint' object has no attribute 'logger'

During handling of the above exception, another exception occurred:

Traceback (most recent call last):
  File "/home/ec2-user/venv/lib64/python3.9/site-packages/flask/app.py", line 891, in finalize_request
    response = self.process_response(response)
  File "/home/ec2-user/venv/lib64/python3.9/site-packages/flask/app.py", line 1267, in process_response
    response = self.ensure_sync(func)(response)
  File "/home/ec2-user/BluestPeakBackend/project/frameworks_and_drivers/app.py", line 85, in after_request
    if not EnterpriseDao.enterprise_has_paid(enterprise_id):
  File "/home/ec2-user/BluestPeakBackend/project/interface_adapters/dao/enterpriseDao.py", line 64, in enterprise_has_paid
    enterprise = enterprises.find_one({'_id':enterprise_id})
  File "/home/ec2-user/venv/lib64/python3.9/site-packages/pymongo/collection.py", line 1224, in find_one
    for result in cursor.limit(-1):
  File "/home/ec2-user/venv/lib64/python3.9/site-packages/pymongo/cursor.py", line 1176, in next
    if len(self.__data) or self._refresh():
  File "/home/ec2-user/venv/lib64/python3.9/site-packages/pymongo/cursor.py", line 1070, in _refresh
    self.__session = self.__collection.database.client._ensure_session()
  File "/home/ec2-user/venv/lib64/python3.9/site-packages/pymongo/mongo_client.py", line 1391, in _ensure_session
    return self.start_session(causal_consistency=False)
  File "/home/ec2-user/venv/lib64/python3.9/site-packages/pymongo/mongo_client.py", line 1369, in start_session
    server_session = self._get_server_session()
  File "/home/ec2-user/venv/lib64/python3.9/site-packages/pymongo/mongo_client.py", line 1377, in _get_server_session
    return self._topology.get_server_session()
  File "/home/ec2-user/venv/lib64/python3.9/site-packages/pymongo/topology.py", line 418, in get_server_session
    self._select_servers_loop(
  File "/home/ec2-user/venv/lib64/python3.9/site-packages/pymongo/topology.py", line 198, in _select_servers_loop
    raise ServerSelectionTimeoutError(
pymongo.errors.ServerSelectionTimeoutError: SSL handshake failed: [SSL: TLSV1_ALERT_INTERNAL_ERROR] tlsv1 alert internal error (_ssl.c:1129),SSL handshake failed: [SSL: TLSV1_ALERT_INTERNAL_ERROR] tlsv1 alert internal error (_ssl.c:1129),SSL handshake failed: [SSL: TLSV1_ALERT_INTERNAL_ERROR] tlsv1 alert internal error (_ssl.c:1129)
[2023-12-15 16:41:21,250] ERROR in app: Exception on /product/result [GET]
Traceback (most recent call last):
  File "/home/ec2-user/venv/lib64/python3.9/site-packages/flask/app.py", line 1455, in wsgi_app
    response = self.full_dispatch_request()
  File "/home/ec2-user/venv/lib64/python3.9/site-packages/flask/app.py", line 869, in full_dispatch_request
    rv = self.handle_user_exception(e)
  File "/home/ec2-user/venv/lib64/python3.9/site-packages/flask_cors/extension.py", line 176, in wrapped_function
    return cors_after_request(app.make_response(f(*args, **kwargs)))
  File "/home/ec2-user/venv/lib64/python3.9/site-packages/flask/app.py", line 867, in full_dispatch_request
    rv = self.dispatch_request()
  File "/home/ec2-user/venv/lib64/python3.9/site-packages/flask/app.py", line 852, in dispatch_request
    return self.ensure_sync(self.view_functions[rule.endpoint])(**view_args)
  File "/home/ec2-user/BluestPeakBackend/project/frameworks_and_drivers/controllers/product.py", line 18, in get_products
    """Returns a list with all the products from the data base."""
AttributeError: 'Blueprint' object has no attribute 'logger'
[2023-12-15 16:41:51,618] ERROR in app: Request finalizing failed with an error while handling an error
Traceback (most recent call last):
  File "/home/ec2-user/venv/lib64/python3.9/site-packages/flask/app.py", line 1455, in wsgi_app
    response = self.full_dispatch_request()
  File "/home/ec2-user/venv/lib64/python3.9/site-packages/flask/app.py", line 869, in full_dispatch_request
    rv = self.handle_user_exception(e)
  File "/home/ec2-user/venv/lib64/python3.9/site-packages/flask_cors/extension.py", line 176, in wrapped_function
    return cors_after_request(app.make_response(f(*args, **kwargs)))
  File "/home/ec2-user/venv/lib64/python3.9/site-packages/flask/app.py", line 867, in full_dispatch_request
    rv = self.dispatch_request()
  File "/home/ec2-user/venv/lib64/python3.9/site-packages/flask/app.py", line 852, in dispatch_request
    return self.ensure_sync(self.view_functions[rule.endpoint])(**view_args)
  File "/home/ec2-user/BluestPeakBackend/project/frameworks_and_drivers/controllers/product.py", line 18, in get_products
    """Returns a list with all the products from the data base."""
AttributeError: 'Blueprint' object has no attribute 'logger'

During handling of the above exception, another exception occurred:

Traceback (most recent call last):
  File "/home/ec2-user/venv/lib64/python3.9/site-packages/flask/app.py", line 891, in finalize_request
    response = self.process_response(response)
  File "/home/ec2-user/venv/lib64/python3.9/site-packages/flask/app.py", line 1267, in process_response
    response = self.ensure_sync(func)(response)
  File "/home/ec2-user/BluestPeakBackend/project/frameworks_and_drivers/app.py", line 85, in after_request
    if not EnterpriseDao.enterprise_has_paid(enterprise_id):
  File "/home/ec2-user/BluestPeakBackend/project/interface_adapters/dao/enterpriseDao.py", line 64, in enterprise_has_paid
    enterprise = enterprises.find_one({'_id':enterprise_id})
  File "/home/ec2-user/venv/lib64/python3.9/site-packages/pymongo/collection.py", line 1224, in find_one
    for result in cursor.limit(-1):
  File "/home/ec2-user/venv/lib64/python3.9/site-packages/pymongo/cursor.py", line 1176, in next
    if len(self.__data) or self._refresh():
  File "/home/ec2-user/venv/lib64/python3.9/site-packages/pymongo/cursor.py", line 1070, in _refresh
    self.__session = self.__collection.database.client._ensure_session()
  File "/home/ec2-user/venv/lib64/python3.9/site-packages/pymongo/mongo_client.py", line 1391, in _ensure_session
    return self.start_session(causal_consistency=False)
  File "/home/ec2-user/venv/lib64/python3.9/site-packages/pymongo/mongo_client.py", line 1369, in start_session
    server_session = self._get_server_session()
  File "/home/ec2-user/venv/lib64/python3.9/site-packages/pymongo/mongo_client.py", line 1377, in _get_server_session
    return self._topology.get_server_session()
  File "/home/ec2-user/venv/lib64/python3.9/site-packages/pymongo/topology.py", line 418, in get_server_session
    self._select_servers_loop(
  File "/home/ec2-user/venv/lib64/python3.9/site-packages/pymongo/topology.py", line 198, in _select_servers_loop
    raise ServerSelectionTimeoutError(
pymongo.errors.ServerSelectionTimeoutError: SSL handshake failed: [SSL: TLSV1_ALERT_INTERNAL_ERROR] tlsv1 alert internal error (_ssl.c:1129),SSL handshake failed: [SSL: TLSV1_ALERT_INTERNAL_ERROR] tlsv1 alert internal error (_ssl.c:1129),SSL handshake failed: [SSL: TLSV1_ALERT_INTERNAL_ERROR] tlsv1 alert internal error (_ssl.c:1129)
[2023-12-15 16:42:13 +0000] [129128] [INFO] Handling signal: term
[2023-12-15 16:42:13 +0000] [129130] [INFO] Worker exiting (pid: 129130)
[2023-12-15 16:42:13 +0000] [129131] [INFO] Worker exiting (pid: 129131)
[2023-12-15 16:42:13 +0000] [129132] [INFO] Worker exiting (pid: 129132)
[2023-12-15 16:42:14 +0000] [129128] [INFO] Shutting down: Master
[2023-12-15 16:42:14 +0000] [130050] [INFO] Starting gunicorn 21.2.0
[2023-12-15 16:42:14 +0000] [130050] [INFO] Listening at: http://0.0.0.0:8000 (130050)
[2023-12-15 16:42:14 +0000] [130050] [INFO] Using worker: sync
[2023-12-15 16:42:14 +0000] [130051] [INFO] Booting worker with pid: 130051
[2023-12-15 16:42:14 +0000] [130052] [INFO] Booting worker with pid: 130052
[2023-12-15 16:42:14 +0000] [130053] [INFO] Booting worker with pid: 130053
[2023-12-15 16:42:15 +0000] [130051] [ERROR] Exception in worker process
Traceback (most recent call last):
  File "/home/ec2-user/venv/lib64/python3.9/site-packages/gunicorn/arbiter.py", line 609, in spawn_worker
    worker.init_process()
  File "/home/ec2-user/venv/lib64/python3.9/site-packages/gunicorn/workers/base.py", line 134, in init_process
    self.load_wsgi()
  File "/home/ec2-user/venv/lib64/python3.9/site-packages/gunicorn/workers/base.py", line 146, in load_wsgi
    self.wsgi = self.app.wsgi()
  File "/home/ec2-user/venv/lib64/python3.9/site-packages/gunicorn/app/base.py", line 67, in wsgi
    self.callable = self.load()
  File "/home/ec2-user/venv/lib64/python3.9/site-packages/gunicorn/app/wsgiapp.py", line 58, in load
    return self.load_wsgiapp()
  File "/home/ec2-user/venv/lib64/python3.9/site-packages/gunicorn/app/wsgiapp.py", line 48, in load_wsgiapp
    return util.import_app(self.app_uri)
  File "/home/ec2-user/venv/lib64/python3.9/site-packages/gunicorn/util.py", line 371, in import_app
    mod = importlib.import_module(module)
  File "/usr/lib64/python3.9/importlib/__init__.py", line 127, in import_module
    return _bootstrap._gcd_import(name[level:], package, level)
  File "<frozen importlib._bootstrap>", line 1030, in _gcd_import
  File "<frozen importlib._bootstrap>", line 1007, in _find_and_load
  File "<frozen importlib._bootstrap>", line 986, in _find_and_load_unlocked
  File "<frozen importlib._bootstrap>", line 680, in _load_unlocked
  File "<frozen importlib._bootstrap_external>", line 850, in exec_module
  File "<frozen importlib._bootstrap>", line 228, in _call_with_frames_removed
  File "/home/ec2-user/BluestPeakBackend/main.py", line 3, in <module>
    from project.frameworks_and_drivers.app import create_app
  File "/home/ec2-user/BluestPeakBackend/project/frameworks_and_drivers/app.py", line 4, in <module>
    from project.frameworks_and_drivers.controllers.product import bpproducts as product
  File "/home/ec2-user/BluestPeakBackend/project/frameworks_and_drivers/controllers/product.py", line 11
    from project.frameworks_and_drivers.decorators import required_authfrom flask import current_app
                                                                            ^
SyntaxError: invalid syntax
[2023-12-15 16:42:15 +0000] [130051] [INFO] Worker exiting (pid: 130051)
[2023-12-15 16:42:15 +0000] [130052] [ERROR] Exception in worker process
Traceback (most recent call last):
  File "/home/ec2-user/venv/lib64/python3.9/site-packages/gunicorn/arbiter.py", line 609, in spawn_worker
    worker.init_process()
  File "/home/ec2-user/venv/lib64/python3.9/site-packages/gunicorn/workers/base.py", line 134, in init_process
    self.load_wsgi()
  File "/home/ec2-user/venv/lib64/python3.9/site-packages/gunicorn/workers/base.py", line 146, in load_wsgi
    self.wsgi = self.app.wsgi()
  File "/home/ec2-user/venv/lib64/python3.9/site-packages/gunicorn/app/base.py", line 67, in wsgi
    self.callable = self.load()
  File "/home/ec2-user/venv/lib64/python3.9/site-packages/gunicorn/app/wsgiapp.py", line 58, in load
    return self.load_wsgiapp()
  File "/home/ec2-user/venv/lib64/python3.9/site-packages/gunicorn/app/wsgiapp.py", line 48, in load_wsgiapp
    return util.import_app(self.app_uri)
  File "/home/ec2-user/venv/lib64/python3.9/site-packages/gunicorn/util.py", line 371, in import_app
    mod = importlib.import_module(module)
  File "/usr/lib64/python3.9/importlib/__init__.py", line 127, in import_module
    return _bootstrap._gcd_import(name[level:], package, level)
  File "<frozen importlib._bootstrap>", line 1030, in _gcd_import
  File "<frozen importlib._bootstrap>", line 1007, in _find_and_load
  File "<frozen importlib._bootstrap>", line 986, in _find_and_load_unlocked
  File "<frozen importlib._bootstrap>", line 680, in _load_unlocked
  File "<frozen importlib._bootstrap_external>", line 850, in exec_module
  File "<frozen importlib._bootstrap>", line 228, in _call_with_frames_removed
  File "/home/ec2-user/BluestPeakBackend/main.py", line 3, in <module>
    from project.frameworks_and_drivers.app import create_app
  File "/home/ec2-user/BluestPeakBackend/project/frameworks_and_drivers/app.py", line 4, in <module>
    from project.frameworks_and_drivers.controllers.product import bpproducts as product
  File "/home/ec2-user/BluestPeakBackend/project/frameworks_and_drivers/controllers/product.py", line 11
    from project.frameworks_and_drivers.decorators import required_authfrom flask import current_app
                                                                            ^
SyntaxError: invalid syntax
[2023-12-15 16:42:15 +0000] [130052] [INFO] Worker exiting (pid: 130052)
[2023-12-15 16:42:15 +0000] [130053] [ERROR] Exception in worker process
Traceback (most recent call last):
  File "/home/ec2-user/venv/lib64/python3.9/site-packages/gunicorn/arbiter.py", line 609, in spawn_worker
    worker.init_process()
  File "/home/ec2-user/venv/lib64/python3.9/site-packages/gunicorn/workers/base.py", line 134, in init_process
    self.load_wsgi()
  File "/home/ec2-user/venv/lib64/python3.9/site-packages/gunicorn/workers/base.py", line 146, in load_wsgi
    self.wsgi = self.app.wsgi()
  File "/home/ec2-user/venv/lib64/python3.9/site-packages/gunicorn/app/base.py", line 67, in wsgi
    self.callable = self.load()
  File "/home/ec2-user/venv/lib64/python3.9/site-packages/gunicorn/app/wsgiapp.py", line 58, in load
    return self.load_wsgiapp()
  File "/home/ec2-user/venv/lib64/python3.9/site-packages/gunicorn/app/wsgiapp.py", line 48, in load_wsgiapp
    return util.import_app(self.app_uri)
  File "/home/ec2-user/venv/lib64/python3.9/site-packages/gunicorn/util.py", line 371, in import_app
    mod = importlib.import_module(module)
  File "/usr/lib64/python3.9/importlib/__init__.py", line 127, in import_module
    return _bootstrap._gcd_import(name[level:], package, level)
  File "<frozen importlib._bootstrap>", line 1030, in _gcd_import
  File "<frozen importlib._bootstrap>", line 1007, in _find_and_load
  File "<frozen importlib._bootstrap>", line 986, in _find_and_load_unlocked
  File "<frozen importlib._bootstrap>", line 680, in _load_unlocked
  File "<frozen importlib._bootstrap_external>", line 850, in exec_module
  File "<frozen importlib._bootstrap>", line 228, in _call_with_frames_removed
  File "/home/ec2-user/BluestPeakBackend/main.py", line 3, in <module>
    from project.frameworks_and_drivers.app import create_app
  File "/home/ec2-user/BluestPeakBackend/project/frameworks_and_drivers/app.py", line 4, in <module>
    from project.frameworks_and_drivers.controllers.product import bpproducts as product
  File "/home/ec2-user/BluestPeakBackend/project/frameworks_and_drivers/controllers/product.py", line 11
    from project.frameworks_and_drivers.decorators import required_authfrom flask import current_app
                                                                            ^
SyntaxError: invalid syntax
[2023-12-15 16:42:15 +0000] [130053] [INFO] Worker exiting (pid: 130053)
[2023-12-15 16:42:15 +0000] [130050] [ERROR] Worker (pid:130051) exited with code 3
[2023-12-15 16:42:16 +0000] [130050] [ERROR] Worker (pid:130052) exited with code 3
[2023-12-15 16:44:55 +0000] [130285] [INFO] Starting gunicorn 21.2.0
[2023-12-15 16:44:55 +0000] [130285] [INFO] Listening at: http://0.0.0.0:8000 (130285)
[2023-12-15 16:44:55 +0000] [130285] [INFO] Using worker: sync
[2023-12-15 16:44:55 +0000] [130286] [INFO] Booting worker with pid: 130286
[2023-12-15 16:44:55 +0000] [130287] [INFO] Booting worker with pid: 130287
[2023-12-15 16:44:55 +0000] [130288] [INFO] Booting worker with pid: 130288
[2023-12-15 16:44:56 +0000] [130286] [ERROR] Exception in worker process
Traceback (most recent call last):
  File "/home/ec2-user/venv/lib64/python3.9/site-packages/gunicorn/arbiter.py", line 609, in spawn_worker
    worker.init_process()
  File "/home/ec2-user/venv/lib64/python3.9/site-packages/gunicorn/workers/base.py", line 134, in init_process
    self.load_wsgi()
  File "/home/ec2-user/venv/lib64/python3.9/site-packages/gunicorn/workers/base.py", line 146, in load_wsgi
    self.wsgi = self.app.wsgi()
  File "/home/ec2-user/venv/lib64/python3.9/site-packages/gunicorn/app/base.py", line 67, in wsgi
    self.callable = self.load()
  File "/home/ec2-user/venv/lib64/python3.9/site-packages/gunicorn/app/wsgiapp.py", line 58, in load
    return self.load_wsgiapp()
  File "/home/ec2-user/venv/lib64/python3.9/site-packages/gunicorn/app/wsgiapp.py", line 48, in load_wsgiapp
    return util.import_app(self.app_uri)
  File "/home/ec2-user/venv/lib64/python3.9/site-packages/gunicorn/util.py", line 371, in import_app
    mod = importlib.import_module(module)
  File "/usr/lib64/python3.9/importlib/__init__.py", line 127, in import_module
    return _bootstrap._gcd_import(name[level:], package, level)
  File "<frozen importlib._bootstrap>", line 1030, in _gcd_import
  File "<frozen importlib._bootstrap>", line 1007, in _find_and_load
  File "<frozen importlib._bootstrap>", line 986, in _find_and_load_unlocked
  File "<frozen importlib._bootstrap>", line 680, in _load_unlocked
  File "<frozen importlib._bootstrap_external>", line 850, in exec_module
  File "<frozen importlib._bootstrap>", line 228, in _call_with_frames_removed
  File "/home/ec2-user/BluestPeakBackend/main.py", line 3, in <module>
    from project.frameworks_and_drivers.app import create_app
  File "/home/ec2-user/BluestPeakBackend/project/frameworks_and_drivers/app.py", line 4, in <module>
    from project.frameworks_and_drivers.controllers.product import bpproducts as product
  File "/home/ec2-user/BluestPeakBackend/project/frameworks_and_drivers/controllers/product.py", line 11
    from project.frameworks_and_drivers.decorators
                                                  ^
SyntaxError: invalid syntax
[2023-12-15 16:44:56 +0000] [130286] [INFO] Worker exiting (pid: 130286)
[2023-12-15 16:44:57 +0000] [130287] [ERROR] Exception in worker process
Traceback (most recent call last):
  File "/home/ec2-user/venv/lib64/python3.9/site-packages/gunicorn/arbiter.py", line 609, in spawn_worker
    worker.init_process()
  File "/home/ec2-user/venv/lib64/python3.9/site-packages/gunicorn/workers/base.py", line 134, in init_process
    self.load_wsgi()
  File "/home/ec2-user/venv/lib64/python3.9/site-packages/gunicorn/workers/base.py", line 146, in load_wsgi
    self.wsgi = self.app.wsgi()
  File "/home/ec2-user/venv/lib64/python3.9/site-packages/gunicorn/app/base.py", line 67, in wsgi
    self.callable = self.load()
  File "/home/ec2-user/venv/lib64/python3.9/site-packages/gunicorn/app/wsgiapp.py", line 58, in load
    return self.load_wsgiapp()
  File "/home/ec2-user/venv/lib64/python3.9/site-packages/gunicorn/app/wsgiapp.py", line 48, in load_wsgiapp
    return util.import_app(self.app_uri)
  File "/home/ec2-user/venv/lib64/python3.9/site-packages/gunicorn/util.py", line 371, in import_app
    mod = importlib.import_module(module)
  File "/usr/lib64/python3.9/importlib/__init__.py", line 127, in import_module
    return _bootstrap._gcd_import(name[level:], package, level)
  File "<frozen importlib._bootstrap>", line 1030, in _gcd_import
  File "<frozen importlib._bootstrap>", line 1007, in _find_and_load
  File "<frozen importlib._bootstrap>", line 986, in _find_and_load_unlocked
  File "<frozen importlib._bootstrap>", line 680, in _load_unlocked
  File "<frozen importlib._bootstrap_external>", line 850, in exec_module
  File "<frozen importlib._bootstrap>", line 228, in _call_with_frames_removed
  File "/home/ec2-user/BluestPeakBackend/main.py", line 3, in <module>
    from project.frameworks_and_drivers.app import create_app
  File "/home/ec2-user/BluestPeakBackend/project/frameworks_and_drivers/app.py", line 4, in <module>
    from project.frameworks_and_drivers.controllers.product import bpproducts as product
  File "/home/ec2-user/BluestPeakBackend/project/frameworks_and_drivers/controllers/product.py", line 11
    from project.frameworks_and_drivers.decorators
                                                  ^
SyntaxError: invalid syntax
[2023-12-15 16:44:57 +0000] [130288] [ERROR] Exception in worker process
Traceback (most recent call last):
  File "/home/ec2-user/venv/lib64/python3.9/site-packages/gunicorn/arbiter.py", line 609, in spawn_worker
    worker.init_process()
  File "/home/ec2-user/venv/lib64/python3.9/site-packages/gunicorn/workers/base.py", line 134, in init_process
    self.load_wsgi()
  File "/home/ec2-user/venv/lib64/python3.9/site-packages/gunicorn/workers/base.py", line 146, in load_wsgi
    self.wsgi = self.app.wsgi()
  File "/home/ec2-user/venv/lib64/python3.9/site-packages/gunicorn/app/base.py", line 67, in wsgi
    self.callable = self.load()
  File "/home/ec2-user/venv/lib64/python3.9/site-packages/gunicorn/app/wsgiapp.py", line 58, in load
    return self.load_wsgiapp()
  File "/home/ec2-user/venv/lib64/python3.9/site-packages/gunicorn/app/wsgiapp.py", line 48, in load_wsgiapp
    return util.import_app(self.app_uri)
  File "/home/ec2-user/venv/lib64/python3.9/site-packages/gunicorn/util.py", line 371, in import_app
    mod = importlib.import_module(module)
  File "/usr/lib64/python3.9/importlib/__init__.py", line 127, in import_module
    return _bootstrap._gcd_import(name[level:], package, level)
  File "<frozen importlib._bootstrap>", line 1030, in _gcd_import
  File "<frozen importlib._bootstrap>", line 1007, in _find_and_load
  File "<frozen importlib._bootstrap>", line 986, in _find_and_load_unlocked
  File "<frozen importlib._bootstrap>", line 680, in _load_unlocked
  File "<frozen importlib._bootstrap_external>", line 850, in exec_module
  File "<frozen importlib._bootstrap>", line 228, in _call_with_frames_removed
  File "/home/ec2-user/BluestPeakBackend/main.py", line 3, in <module>
    from project.frameworks_and_drivers.app import create_app
  File "/home/ec2-user/BluestPeakBackend/project/frameworks_and_drivers/app.py", line 4, in <module>
    from project.frameworks_and_drivers.controllers.product import bpproducts as product
  File "/home/ec2-user/BluestPeakBackend/project/frameworks_and_drivers/controllers/product.py", line 11
    from project.frameworks_and_drivers.decorators
                                                  ^
SyntaxError: invalid syntax
[2023-12-15 16:44:57 +0000] [130287] [INFO] Worker exiting (pid: 130287)
[2023-12-15 16:44:57 +0000] [130288] [INFO] Worker exiting (pid: 130288)
[2023-12-15 16:44:57 +0000] [130285] [ERROR] Worker (pid:130286) exited with code 3
[2023-12-15 16:44:57 +0000] [130285] [ERROR] Worker (pid:130288) exited with code 3
[2023-12-15 16:45:34 +0000] [130419] [INFO] Starting gunicorn 21.2.0
[2023-12-15 16:45:34 +0000] [130419] [INFO] Listening at: http://0.0.0.0:8000 (130419)
[2023-12-15 16:45:34 +0000] [130419] [INFO] Using worker: sync
[2023-12-15 16:45:34 +0000] [130420] [INFO] Booting worker with pid: 130420
[2023-12-15 16:45:34 +0000] [130421] [INFO] Booting worker with pid: 130421
[2023-12-15 16:45:34 +0000] [130422] [INFO] Booting worker with pid: 130422
[2023-12-15 16:45:35 +0000] [130420] [ERROR] Exception in worker process
Traceback (most recent call last):
  File "/home/ec2-user/venv/lib64/python3.9/site-packages/gunicorn/arbiter.py", line 609, in spawn_worker
    worker.init_process()
  File "/home/ec2-user/venv/lib64/python3.9/site-packages/gunicorn/workers/base.py", line 134, in init_process
    self.load_wsgi()
  File "/home/ec2-user/venv/lib64/python3.9/site-packages/gunicorn/workers/base.py", line 146, in load_wsgi
    self.wsgi = self.app.wsgi()
  File "/home/ec2-user/venv/lib64/python3.9/site-packages/gunicorn/app/base.py", line 67, in wsgi
    self.callable = self.load()
  File "/home/ec2-user/venv/lib64/python3.9/site-packages/gunicorn/app/wsgiapp.py", line 58, in load
    return self.load_wsgiapp()
  File "/home/ec2-user/venv/lib64/python3.9/site-packages/gunicorn/app/wsgiapp.py", line 48, in load_wsgiapp
    return util.import_app(self.app_uri)
  File "/home/ec2-user/venv/lib64/python3.9/site-packages/gunicorn/util.py", line 371, in import_app
    mod = importlib.import_module(module)
  File "/usr/lib64/python3.9/importlib/__init__.py", line 127, in import_module
    return _bootstrap._gcd_import(name[level:], package, level)
  File "<frozen importlib._bootstrap>", line 1030, in _gcd_import
  File "<frozen importlib._bootstrap>", line 1007, in _find_and_load
  File "<frozen importlib._bootstrap>", line 986, in _find_and_load_unlocked
  File "<frozen importlib._bootstrap>", line 680, in _load_unlocked
  File "<frozen importlib._bootstrap_external>", line 850, in exec_module
  File "<frozen importlib._bootstrap>", line 228, in _call_with_frames_removed
  File "/home/ec2-user/BluestPeakBackend/main.py", line 3, in <module>
    from project.frameworks_and_drivers.app import create_app
  File "/home/ec2-user/BluestPeakBackend/project/frameworks_and_drivers/app.py", line 4, in <module>
    from project.frameworks_and_drivers.controllers.product import bpproducts as product
  File "/home/ec2-user/BluestPeakBackend/project/frameworks_and_drivers/controllers/product.py", line 12
    import required_authfrom flask import current_app
                             ^
SyntaxError: invalid syntax
[2023-12-15 16:45:35 +0000] [130420] [INFO] Worker exiting (pid: 130420)
[2023-12-15 16:45:35 +0000] [130421] [ERROR] Exception in worker process
Traceback (most recent call last):
  File "/home/ec2-user/venv/lib64/python3.9/site-packages/gunicorn/arbiter.py", line 609, in spawn_worker
    worker.init_process()
  File "/home/ec2-user/venv/lib64/python3.9/site-packages/gunicorn/workers/base.py", line 134, in init_process
    self.load_wsgi()
  File "/home/ec2-user/venv/lib64/python3.9/site-packages/gunicorn/workers/base.py", line 146, in load_wsgi
    self.wsgi = self.app.wsgi()
  File "/home/ec2-user/venv/lib64/python3.9/site-packages/gunicorn/app/base.py", line 67, in wsgi
    self.callable = self.load()
  File "/home/ec2-user/venv/lib64/python3.9/site-packages/gunicorn/app/wsgiapp.py", line 58, in load
    return self.load_wsgiapp()
  File "/home/ec2-user/venv/lib64/python3.9/site-packages/gunicorn/app/wsgiapp.py", line 48, in load_wsgiapp
    return util.import_app(self.app_uri)
  File "/home/ec2-user/venv/lib64/python3.9/site-packages/gunicorn/util.py", line 371, in import_app
    mod = importlib.import_module(module)
  File "/usr/lib64/python3.9/importlib/__init__.py", line 127, in import_module
    return _bootstrap._gcd_import(name[level:], package, level)
  File "<frozen importlib._bootstrap>", line 1030, in _gcd_import
  File "<frozen importlib._bootstrap>", line 1007, in _find_and_load
  File "<frozen importlib._bootstrap>", line 986, in _find_and_load_unlocked
  File "<frozen importlib._bootstrap>", line 680, in _load_unlocked
  File "<frozen importlib._bootstrap_external>", line 850, in exec_module
  File "<frozen importlib._bootstrap>", line 228, in _call_with_frames_removed
  File "/home/ec2-user/BluestPeakBackend/main.py", line 3, in <module>
    from project.frameworks_and_drivers.app import create_app
  File "/home/ec2-user/BluestPeakBackend/project/frameworks_and_drivers/app.py", line 4, in <module>
    from project.frameworks_and_drivers.controllers.product import bpproducts as product
  File "/home/ec2-user/BluestPeakBackend/project/frameworks_and_drivers/controllers/product.py", line 12
    import required_authfrom flask import current_app
                             ^
SyntaxError: invalid syntax
[2023-12-15 16:45:35 +0000] [130421] [INFO] Worker exiting (pid: 130421)
[2023-12-15 16:45:35 +0000] [130422] [ERROR] Exception in worker process
Traceback (most recent call last):
  File "/home/ec2-user/venv/lib64/python3.9/site-packages/gunicorn/arbiter.py", line 609, in spawn_worker
    worker.init_process()
  File "/home/ec2-user/venv/lib64/python3.9/site-packages/gunicorn/workers/base.py", line 134, in init_process
    self.load_wsgi()
  File "/home/ec2-user/venv/lib64/python3.9/site-packages/gunicorn/workers/base.py", line 146, in load_wsgi
    self.wsgi = self.app.wsgi()
  File "/home/ec2-user/venv/lib64/python3.9/site-packages/gunicorn/app/base.py", line 67, in wsgi
    self.callable = self.load()
  File "/home/ec2-user/venv/lib64/python3.9/site-packages/gunicorn/app/wsgiapp.py", line 58, in load
    return self.load_wsgiapp()
  File "/home/ec2-user/venv/lib64/python3.9/site-packages/gunicorn/app/wsgiapp.py", line 48, in load_wsgiapp
    return util.import_app(self.app_uri)
  File "/home/ec2-user/venv/lib64/python3.9/site-packages/gunicorn/util.py", line 371, in import_app
    mod = importlib.import_module(module)
  File "/usr/lib64/python3.9/importlib/__init__.py", line 127, in import_module
    return _bootstrap._gcd_import(name[level:], package, level)
  File "<frozen importlib._bootstrap>", line 1030, in _gcd_import
  File "<frozen importlib._bootstrap>", line 1007, in _find_and_load
  File "<frozen importlib._bootstrap>", line 986, in _find_and_load_unlocked
  File "<frozen importlib._bootstrap>", line 680, in _load_unlocked
  File "<frozen importlib._bootstrap_external>", line 850, in exec_module
  File "<frozen importlib._bootstrap>", line 228, in _call_with_frames_removed
  File "/home/ec2-user/BluestPeakBackend/main.py", line 3, in <module>
    from project.frameworks_and_drivers.app import create_app
  File "/home/ec2-user/BluestPeakBackend/project/frameworks_and_drivers/app.py", line 4, in <module>
    from project.frameworks_and_drivers.controllers.product import bpproducts as product
  File "/home/ec2-user/BluestPeakBackend/project/frameworks_and_drivers/controllers/product.py", line 12
    import required_authfrom flask import current_app
                             ^
SyntaxError: invalid syntax
[2023-12-15 16:45:35 +0000] [130422] [INFO] Worker exiting (pid: 130422)
[2023-12-15 16:45:36 +0000] [130419] [ERROR] Worker (pid:130420) exited with code 3
[2023-12-15 16:45:36 +0000] [130419] [ERROR] Worker (pid:130421) exited with code 3
[2023-12-15 16:46:01 +0000] [130503] [INFO] Starting gunicorn 21.2.0
[2023-12-15 16:46:01 +0000] [130503] [INFO] Listening at: http://0.0.0.0:8000 (130503)
[2023-12-15 16:46:01 +0000] [130503] [INFO] Using worker: sync
[2023-12-15 16:46:01 +0000] [130504] [INFO] Booting worker with pid: 130504
[2023-12-15 16:46:01 +0000] [130505] [INFO] Booting worker with pid: 130505
[2023-12-15 16:46:01 +0000] [130506] [INFO] Booting worker with pid: 130506
[2023-12-15 16:46:02 +0000] [130504] [ERROR] Exception in worker process
Traceback (most recent call last):
  File "/home/ec2-user/venv/lib64/python3.9/site-packages/gunicorn/arbiter.py", line 609, in spawn_worker
    worker.init_process()
  File "/home/ec2-user/venv/lib64/python3.9/site-packages/gunicorn/workers/base.py", line 134, in init_process
    self.load_wsgi()
  File "/home/ec2-user/venv/lib64/python3.9/site-packages/gunicorn/workers/base.py", line 146, in load_wsgi
    self.wsgi = self.app.wsgi()
  File "/home/ec2-user/venv/lib64/python3.9/site-packages/gunicorn/app/base.py", line 67, in wsgi
    self.callable = self.load()
  File "/home/ec2-user/venv/lib64/python3.9/site-packages/gunicorn/app/wsgiapp.py", line 58, in load
    return self.load_wsgiapp()
  File "/home/ec2-user/venv/lib64/python3.9/site-packages/gunicorn/app/wsgiapp.py", line 48, in load_wsgiapp
    return util.import_app(self.app_uri)
  File "/home/ec2-user/venv/lib64/python3.9/site-packages/gunicorn/util.py", line 371, in import_app
    mod = importlib.import_module(module)
  File "/usr/lib64/python3.9/importlib/__init__.py", line 127, in import_module
    return _bootstrap._gcd_import(name[level:], package, level)
  File "<frozen importlib._bootstrap>", line 1030, in _gcd_import
  File "<frozen importlib._bootstrap>", line 1007, in _find_and_load
  File "<frozen importlib._bootstrap>", line 986, in _find_and_load_unlocked
  File "<frozen importlib._bootstrap>", line 680, in _load_unlocked
  File "<frozen importlib._bootstrap_external>", line 850, in exec_module
  File "<frozen importlib._bootstrap>", line 228, in _call_with_frames_removed
  File "/home/ec2-user/BluestPeakBackend/main.py", line 3, in <module>
    from project.frameworks_and_drivers.app import create_app
  File "/home/ec2-user/BluestPeakBackend/project/frameworks_and_drivers/app.py", line 4, in <module>
    from project.frameworks_and_drivers.controllers.product import bpproducts as product
  File "/home/ec2-user/BluestPeakBackend/project/frameworks_and_drivers/controllers/product.py", line 12, in <module>
    import current_app
ModuleNotFoundError: No module named 'current_app'
[2023-12-15 16:46:02 +0000] [130504] [INFO] Worker exiting (pid: 130504)
[2023-12-15 16:46:02 +0000] [130505] [ERROR] Exception in worker process
Traceback (most recent call last):
  File "/home/ec2-user/venv/lib64/python3.9/site-packages/gunicorn/arbiter.py", line 609, in spawn_worker
    worker.init_process()
  File "/home/ec2-user/venv/lib64/python3.9/site-packages/gunicorn/workers/base.py", line 134, in init_process
    self.load_wsgi()
  File "/home/ec2-user/venv/lib64/python3.9/site-packages/gunicorn/workers/base.py", line 146, in load_wsgi
    self.wsgi = self.app.wsgi()
  File "/home/ec2-user/venv/lib64/python3.9/site-packages/gunicorn/app/base.py", line 67, in wsgi
    self.callable = self.load()
  File "/home/ec2-user/venv/lib64/python3.9/site-packages/gunicorn/app/wsgiapp.py", line 58, in load
    return self.load_wsgiapp()
  File "/home/ec2-user/venv/lib64/python3.9/site-packages/gunicorn/app/wsgiapp.py", line 48, in load_wsgiapp
    return util.import_app(self.app_uri)
  File "/home/ec2-user/venv/lib64/python3.9/site-packages/gunicorn/util.py", line 371, in import_app
    mod = importlib.import_module(module)
  File "/usr/lib64/python3.9/importlib/__init__.py", line 127, in import_module
    return _bootstrap._gcd_import(name[level:], package, level)
  File "<frozen importlib._bootstrap>", line 1030, in _gcd_import
  File "<frozen importlib._bootstrap>", line 1007, in _find_and_load
  File "<frozen importlib._bootstrap>", line 986, in _find_and_load_unlocked
  File "<frozen importlib._bootstrap>", line 680, in _load_unlocked
  File "<frozen importlib._bootstrap_external>", line 850, in exec_module
  File "<frozen importlib._bootstrap>", line 228, in _call_with_frames_removed
  File "/home/ec2-user/BluestPeakBackend/main.py", line 3, in <module>
    from project.frameworks_and_drivers.app import create_app
  File "/home/ec2-user/BluestPeakBackend/project/frameworks_and_drivers/app.py", line 4, in <module>
    from project.frameworks_and_drivers.controllers.product import bpproducts as product
  File "/home/ec2-user/BluestPeakBackend/project/frameworks_and_drivers/controllers/product.py", line 12, in <module>
    import current_app
ModuleNotFoundError: No module named 'current_app'
[2023-12-15 16:46:02 +0000] [130505] [INFO] Worker exiting (pid: 130505)
[2023-12-15 16:46:02 +0000] [130506] [ERROR] Exception in worker process
Traceback (most recent call last):
  File "/home/ec2-user/venv/lib64/python3.9/site-packages/gunicorn/arbiter.py", line 609, in spawn_worker
    worker.init_process()
  File "/home/ec2-user/venv/lib64/python3.9/site-packages/gunicorn/workers/base.py", line 134, in init_process
    self.load_wsgi()
  File "/home/ec2-user/venv/lib64/python3.9/site-packages/gunicorn/workers/base.py", line 146, in load_wsgi
    self.wsgi = self.app.wsgi()
  File "/home/ec2-user/venv/lib64/python3.9/site-packages/gunicorn/app/base.py", line 67, in wsgi
    self.callable = self.load()
  File "/home/ec2-user/venv/lib64/python3.9/site-packages/gunicorn/app/wsgiapp.py", line 58, in load
    return self.load_wsgiapp()
  File "/home/ec2-user/venv/lib64/python3.9/site-packages/gunicorn/app/wsgiapp.py", line 48, in load_wsgiapp
    return util.import_app(self.app_uri)
  File "/home/ec2-user/venv/lib64/python3.9/site-packages/gunicorn/util.py", line 371, in import_app
    mod = importlib.import_module(module)
  File "/usr/lib64/python3.9/importlib/__init__.py", line 127, in import_module
    return _bootstrap._gcd_import(name[level:], package, level)
  File "<frozen importlib._bootstrap>", line 1030, in _gcd_import
  File "<frozen importlib._bootstrap>", line 1007, in _find_and_load
  File "<frozen importlib._bootstrap>", line 986, in _find_and_load_unlocked
  File "<frozen importlib._bootstrap>", line 680, in _load_unlocked
  File "<frozen importlib._bootstrap_external>", line 850, in exec_module
  File "<frozen importlib._bootstrap>", line 228, in _call_with_frames_removed
  File "/home/ec2-user/BluestPeakBackend/main.py", line 3, in <module>
    from project.frameworks_and_drivers.app import create_app
  File "/home/ec2-user/BluestPeakBackend/project/frameworks_and_drivers/app.py", line 4, in <module>
    from project.frameworks_and_drivers.controllers.product import bpproducts as product
  File "/home/ec2-user/BluestPeakBackend/project/frameworks_and_drivers/controllers/product.py", line 12, in <module>
    import current_app
ModuleNotFoundError: No module named 'current_app'
[2023-12-15 16:46:02 +0000] [130506] [INFO] Worker exiting (pid: 130506)
[2023-12-15 16:46:03 +0000] [130503] [ERROR] Worker (pid:130504) exited with code 3
[2023-12-15 16:46:03 +0000] [130503] [ERROR] Worker (pid:130505) exited with code 3
[2023-12-15 16:46:36 +0000] [130634] [INFO] Starting gunicorn 21.2.0
[2023-12-15 16:46:36 +0000] [130634] [INFO] Listening at: http://0.0.0.0:8000 (130634)
[2023-12-15 16:46:36 +0000] [130634] [INFO] Using worker: sync
[2023-12-15 16:46:36 +0000] [130635] [INFO] Booting worker with pid: 130635
[2023-12-15 16:46:36 +0000] [130636] [INFO] Booting worker with pid: 130636
[2023-12-15 16:46:36 +0000] [130637] [INFO] Booting worker with pid: 130637
[2023-12-15 16:50:01,421] ERROR in app: Exception on /product/result [GET]
Traceback (most recent call last):
  File "/home/ec2-user/venv/lib64/python3.9/site-packages/flask/app.py", line 1455, in wsgi_app
    response = self.full_dispatch_request()
  File "/home/ec2-user/venv/lib64/python3.9/site-packages/flask/app.py", line 869, in full_dispatch_request
    rv = self.handle_user_exception(e)
  File "/home/ec2-user/venv/lib64/python3.9/site-packages/flask_cors/extension.py", line 176, in wrapped_function
    return cors_after_request(app.make_response(f(*args, **kwargs)))
  File "/home/ec2-user/venv/lib64/python3.9/site-packages/flask/app.py", line 867, in full_dispatch_request
    rv = self.dispatch_request()
  File "/home/ec2-user/venv/lib64/python3.9/site-packages/flask/app.py", line 852, in dispatch_request
    return self.ensure_sync(self.view_functions[rule.endpoint])(**view_args)
  File "/home/ec2-user/BluestPeakBackend/project/frameworks_and_drivers/controllers/product.py", line 26, in get_products
    product_dicts = interactor.execute(
  File "/home/ec2-user/BluestPeakBackend/project/use_cases/product_interactor.py", line 22, in execute
    product_dicts = self.product_dao.get_products(
  File "/home/ec2-user/BluestPeakBackend/project/interface_adapters/dao/productDao.py", line 19, in get_products
    product_list = [
  File "/home/ec2-user/BluestPeakBackend/project/interface_adapters/dao/productDao.py", line 19, in <listcomp>
    product_list = [
  File "/home/ec2-user/venv/lib64/python3.9/site-packages/pymongo/cursor.py", line 1176, in next
    if len(self.__data) or self._refresh():
  File "/home/ec2-user/venv/lib64/python3.9/site-packages/pymongo/cursor.py", line 1070, in _refresh
    self.__session = self.__collection.database.client._ensure_session()
  File "/home/ec2-user/venv/lib64/python3.9/site-packages/pymongo/mongo_client.py", line 1391, in _ensure_session
    return self.start_session(causal_consistency=False)
  File "/home/ec2-user/venv/lib64/python3.9/site-packages/pymongo/mongo_client.py", line 1369, in start_session
    server_session = self._get_server_session()
  File "/home/ec2-user/venv/lib64/python3.9/site-packages/pymongo/mongo_client.py", line 1377, in _get_server_session
    return self._topology.get_server_session()
  File "/home/ec2-user/venv/lib64/python3.9/site-packages/pymongo/topology.py", line 418, in get_server_session
    self._select_servers_loop(
  File "/home/ec2-user/venv/lib64/python3.9/site-packages/pymongo/topology.py", line 198, in _select_servers_loop
    raise ServerSelectionTimeoutError(
pymongo.errors.ServerSelectionTimeoutError: SSL handshake failed: [SSL: TLSV1_ALERT_INTERNAL_ERROR] tlsv1 alert internal error (_ssl.c:1129),SSL handshake failed: [SSL: TLSV1_ALERT_INTERNAL_ERROR] tlsv1 alert internal error (_ssl.c:1129),SSL handshake failed: [SSL: TLSV1_ALERT_INTERNAL_ERROR] tlsv1 alert internal error (_ssl.c:1129)
[2023-12-15 16:50:01 +0000] [130634] [CRITICAL] WORKER TIMEOUT (pid:130636)
[2023-12-15 16:50:01 +0000] [130636] [INFO] Worker exiting (pid: 130636)
[2023-12-15 16:50:02 +0000] [130634] [ERROR] Worker (pid:130636) exited with code 1
[2023-12-15 16:50:02 +0000] [130634] [ERROR] Worker (pid:130636) exited with code 1.
[2023-12-15 16:50:02 +0000] [130746] [INFO] Booting worker with pid: 130746
[2023-12-15 21:38:31 +0000] [130634] [INFO] Handling signal: term
[2023-12-15 21:38:31 +0000] [130635] [INFO] Worker exiting (pid: 130635)
[2023-12-15 21:38:31 +0000] [130637] [INFO] Worker exiting (pid: 130637)
[2023-12-15 21:38:31 +0000] [130746] [INFO] Worker exiting (pid: 130746)
[2023-12-15 21:38:32 +0000] [130634] [INFO] Shutting down: Master
[2023-12-15 21:38:32 +0000] [138037] [INFO] Starting gunicorn 21.2.0
[2023-12-15 21:38:32 +0000] [138037] [INFO] Listening at: http://0.0.0.0:8000 (138037)
[2023-12-15 21:38:32 +0000] [138037] [INFO] Using worker: sync
[2023-12-15 21:38:32 +0000] [138038] [INFO] Booting worker with pid: 138038
[2023-12-15 21:38:32 +0000] [138039] [INFO] Booting worker with pid: 138039
[2023-12-15 21:38:32 +0000] [138040] [INFO] Booting worker with pid: 138040
[2023-12-15 21:38:33 +0000] [138038] [ERROR] Exception in worker process
Traceback (most recent call last):
  File "/home/ec2-user/venv/lib64/python3.9/site-packages/gunicorn/arbiter.py", line 609, in spawn_worker
    worker.init_process()
  File "/home/ec2-user/venv/lib64/python3.9/site-packages/gunicorn/workers/base.py", line 134, in init_process
    self.load_wsgi()
  File "/home/ec2-user/venv/lib64/python3.9/site-packages/gunicorn/workers/base.py", line 146, in load_wsgi
    self.wsgi = self.app.wsgi()
  File "/home/ec2-user/venv/lib64/python3.9/site-packages/gunicorn/app/base.py", line 67, in wsgi
    self.callable = self.load()
  File "/home/ec2-user/venv/lib64/python3.9/site-packages/gunicorn/app/wsgiapp.py", line 58, in load
    return self.load_wsgiapp()
  File "/home/ec2-user/venv/lib64/python3.9/site-packages/gunicorn/app/wsgiapp.py", line 48, in load_wsgiapp
    return util.import_app(self.app_uri)
  File "/home/ec2-user/venv/lib64/python3.9/site-packages/gunicorn/util.py", line 371, in import_app
    mod = importlib.import_module(module)
  File "/usr/lib64/python3.9/importlib/__init__.py", line 127, in import_module
    return _bootstrap._gcd_import(name[level:], package, level)
  File "<frozen importlib._bootstrap>", line 1030, in _gcd_import
  File "<frozen importlib._bootstrap>", line 1007, in _find_and_load
  File "<frozen importlib._bootstrap>", line 986, in _find_and_load_unlocked
  File "<frozen importlib._bootstrap>", line 680, in _load_unlocked
  File "<frozen importlib._bootstrap_external>", line 850, in exec_module
  File "<frozen importlib._bootstrap>", line 228, in _call_with_frames_removed
  File "/home/ec2-user/BluestPeakBackend/main.py", line 3, in <module>
    from project.frameworks_and_drivers.app import create_app
  File "/home/ec2-user/BluestPeakBackend/project/frameworks_and_drivers/app.py", line 2, in <module>
    from project.frameworks_and_drivers.controllers.rate import bprate as rate
  File "/home/ec2-user/BluestPeakBackend/project/frameworks_and_drivers/controllers/rate.py", line 4, in <module>
    from project.interface_adapters.dao.rateDao import RateDao
  File "/home/ec2-user/BluestPeakBackend/project/interface_adapters/dao/rateDao.py", line 1, in <module>
    from project.frameworks_and_drivers.database import db
  File "/home/ec2-user/BluestPeakBackend/project/frameworks_and_drivers/database.py", line 29, in <module>
    db = MongoConnection.get_instance().db
  File "/home/ec2-user/BluestPeakBackend/project/frameworks_and_drivers/database.py", line 14, in get_instance
    MongoConnection()
  File "/home/ec2-user/BluestPeakBackend/project/frameworks_and_drivers/database.py", line 22, in __init__
    client = MongoClient(MONGO_URI, tlsCAFile=ca)
  File "/home/ec2-user/venv/lib64/python3.9/site-packages/pymongo/mongo_client.py", line 494, in __init__
    keyword_opts = dict(common.validate(k, v)
  File "/home/ec2-user/venv/lib64/python3.9/site-packages/pymongo/mongo_client.py", line 494, in <genexpr>
    keyword_opts = dict(common.validate(k, v)
  File "/home/ec2-user/venv/lib64/python3.9/site-packages/pymongo/common.py", line 569, in validate
    value = validator(option, value)
  File "/home/ec2-user/venv/lib64/python3.9/site-packages/pymongo/common.py", line 127, in raise_config_error
    raise ConfigurationError("Unknown option %s" % (key,))
pymongo.errors.ConfigurationError: Unknown option tlsCAFile
[2023-12-15 21:38:33 +0000] [138038] [INFO] Worker exiting (pid: 138038)
[2023-12-15 21:38:33 +0000] [138037] [ERROR] Worker (pid:138038) exited with code 3
[2023-12-15 21:38:33 +0000] [138039] [ERROR] Exception in worker process
Traceback (most recent call last):
  File "/home/ec2-user/venv/lib64/python3.9/site-packages/gunicorn/arbiter.py", line 609, in spawn_worker
    worker.init_process()
  File "/home/ec2-user/venv/lib64/python3.9/site-packages/gunicorn/workers/base.py", line 134, in init_process
    self.load_wsgi()
  File "/home/ec2-user/venv/lib64/python3.9/site-packages/gunicorn/workers/base.py", line 146, in load_wsgi
    self.wsgi = self.app.wsgi()
  File "/home/ec2-user/venv/lib64/python3.9/site-packages/gunicorn/app/base.py", line 67, in wsgi
    self.callable = self.load()
  File "/home/ec2-user/venv/lib64/python3.9/site-packages/gunicorn/app/wsgiapp.py", line 58, in load
    return self.load_wsgiapp()
  File "/home/ec2-user/venv/lib64/python3.9/site-packages/gunicorn/app/wsgiapp.py", line 48, in load_wsgiapp
    return util.import_app(self.app_uri)
  File "/home/ec2-user/venv/lib64/python3.9/site-packages/gunicorn/util.py", line 371, in import_app
    mod = importlib.import_module(module)
  File "/usr/lib64/python3.9/importlib/__init__.py", line 127, in import_module
    return _bootstrap._gcd_import(name[level:], package, level)
  File "<frozen importlib._bootstrap>", line 1030, in _gcd_import
  File "<frozen importlib._bootstrap>", line 1007, in _find_and_load
  File "<frozen importlib._bootstrap>", line 986, in _find_and_load_unlocked
  File "<frozen importlib._bootstrap>", line 680, in _load_unlocked
  File "<frozen importlib._bootstrap_external>", line 850, in exec_module
  File "<frozen importlib._bootstrap>", line 228, in _call_with_frames_removed
  File "/home/ec2-user/BluestPeakBackend/main.py", line 3, in <module>
    from project.frameworks_and_drivers.app import create_app
  File "/home/ec2-user/BluestPeakBackend/project/frameworks_and_drivers/app.py", line 2, in <module>
    from project.frameworks_and_drivers.controllers.rate import bprate as rate
  File "/home/ec2-user/BluestPeakBackend/project/frameworks_and_drivers/controllers/rate.py", line 4, in <module>
    from project.interface_adapters.dao.rateDao import RateDao
  File "/home/ec2-user/BluestPeakBackend/project/interface_adapters/dao/rateDao.py", line 1, in <module>
    from project.frameworks_and_drivers.database import db
  File "/home/ec2-user/BluestPeakBackend/project/frameworks_and_drivers/database.py", line 29, in <module>
    db = MongoConnection.get_instance().db
  File "/home/ec2-user/BluestPeakBackend/project/frameworks_and_drivers/database.py", line 14, in get_instance
    MongoConnection()
  File "/home/ec2-user/BluestPeakBackend/project/frameworks_and_drivers/database.py", line 22, in __init__
    client = MongoClient(MONGO_URI, tlsCAFile=ca)
  File "/home/ec2-user/venv/lib64/python3.9/site-packages/pymongo/mongo_client.py", line 494, in __init__
    keyword_opts = dict(common.validate(k, v)
  File "/home/ec2-user/venv/lib64/python3.9/site-packages/pymongo/mongo_client.py", line 494, in <genexpr>
    keyword_opts = dict(common.validate(k, v)
  File "/home/ec2-user/venv/lib64/python3.9/site-packages/pymongo/common.py", line 569, in validate
    value = validator(option, value)
  File "/home/ec2-user/venv/lib64/python3.9/site-packages/pymongo/common.py", line 127, in raise_config_error
    raise ConfigurationError("Unknown option %s" % (key,))
pymongo.errors.ConfigurationError: Unknown option tlsCAFile
[2023-12-15 21:38:33 +0000] [138039] [INFO] Worker exiting (pid: 138039)
[2023-12-15 21:38:33 +0000] [138040] [ERROR] Exception in worker process
Traceback (most recent call last):
  File "/home/ec2-user/venv/lib64/python3.9/site-packages/gunicorn/arbiter.py", line 609, in spawn_worker
    worker.init_process()
  File "/home/ec2-user/venv/lib64/python3.9/site-packages/gunicorn/workers/base.py", line 134, in init_process
    self.load_wsgi()
  File "/home/ec2-user/venv/lib64/python3.9/site-packages/gunicorn/workers/base.py", line 146, in load_wsgi
    self.wsgi = self.app.wsgi()
  File "/home/ec2-user/venv/lib64/python3.9/site-packages/gunicorn/app/base.py", line 67, in wsgi
    self.callable = self.load()
  File "/home/ec2-user/venv/lib64/python3.9/site-packages/gunicorn/app/wsgiapp.py", line 58, in load
    return self.load_wsgiapp()
  File "/home/ec2-user/venv/lib64/python3.9/site-packages/gunicorn/app/wsgiapp.py", line 48, in load_wsgiapp
    return util.import_app(self.app_uri)
  File "/home/ec2-user/venv/lib64/python3.9/site-packages/gunicorn/util.py", line 371, in import_app
    mod = importlib.import_module(module)
  File "/usr/lib64/python3.9/importlib/__init__.py", line 127, in import_module
    return _bootstrap._gcd_import(name[level:], package, level)
  File "<frozen importlib._bootstrap>", line 1030, in _gcd_import
  File "<frozen importlib._bootstrap>", line 1007, in _find_and_load
  File "<frozen importlib._bootstrap>", line 986, in _find_and_load_unlocked
  File "<frozen importlib._bootstrap>", line 680, in _load_unlocked
  File "<frozen importlib._bootstrap_external>", line 850, in exec_module
  File "<frozen importlib._bootstrap>", line 228, in _call_with_frames_removed
  File "/home/ec2-user/BluestPeakBackend/main.py", line 3, in <module>
    from project.frameworks_and_drivers.app import create_app
  File "/home/ec2-user/BluestPeakBackend/project/frameworks_and_drivers/app.py", line 2, in <module>
    from project.frameworks_and_drivers.controllers.rate import bprate as rate
  File "/home/ec2-user/BluestPeakBackend/project/frameworks_and_drivers/controllers/rate.py", line 4, in <module>
    from project.interface_adapters.dao.rateDao import RateDao
  File "/home/ec2-user/BluestPeakBackend/project/interface_adapters/dao/rateDao.py", line 1, in <module>
    from project.frameworks_and_drivers.database import db
  File "/home/ec2-user/BluestPeakBackend/project/frameworks_and_drivers/database.py", line 29, in <module>
    db = MongoConnection.get_instance().db
  File "/home/ec2-user/BluestPeakBackend/project/frameworks_and_drivers/database.py", line 14, in get_instance
    MongoConnection()
  File "/home/ec2-user/BluestPeakBackend/project/frameworks_and_drivers/database.py", line 22, in __init__
    client = MongoClient(MONGO_URI, tlsCAFile=ca)
  File "/home/ec2-user/venv/lib64/python3.9/site-packages/pymongo/mongo_client.py", line 494, in __init__
    keyword_opts = dict(common.validate(k, v)
  File "/home/ec2-user/venv/lib64/python3.9/site-packages/pymongo/mongo_client.py", line 494, in <genexpr>
    keyword_opts = dict(common.validate(k, v)
  File "/home/ec2-user/venv/lib64/python3.9/site-packages/pymongo/common.py", line 569, in validate
    value = validator(option, value)
  File "/home/ec2-user/venv/lib64/python3.9/site-packages/pymongo/common.py", line 127, in raise_config_error
    raise ConfigurationError("Unknown option %s" % (key,))
pymongo.errors.ConfigurationError: Unknown option tlsCAFile
[2023-12-15 21:38:33 +0000] [138040] [INFO] Worker exiting (pid: 138040)
[2023-12-15 21:38:33 +0000] [138037] [ERROR] Worker (pid:138039) exited with code 3
[2023-12-15 21:44:11 +0000] [138282] [INFO] Starting gunicorn 21.2.0
[2023-12-15 21:44:11 +0000] [138282] [INFO] Listening at: http://0.0.0.0:8000 (138282)
[2023-12-15 21:44:11 +0000] [138282] [INFO] Using worker: sync
[2023-12-15 21:44:11 +0000] [138283] [INFO] Booting worker with pid: 138283
[2023-12-15 21:44:11 +0000] [138284] [INFO] Booting worker with pid: 138284
[2023-12-15 21:44:11 +0000] [138285] [INFO] Booting worker with pid: 138285
[2023-12-15 21:51:31 +0000] [138282] [CRITICAL] WORKER TIMEOUT (pid:138283)
[2023-12-15 21:51:31 +0000] [138283] [INFO] Worker exiting (pid: 138283)
[2023-12-15 21:51:31 +0000] [138282] [ERROR] Worker (pid:138283) exited with code 1
[2023-12-15 21:51:31 +0000] [138282] [ERROR] Worker (pid:138283) exited with code 1.
[2023-12-15 21:51:31 +0000] [138527] [INFO] Booting worker with pid: 138527
[2023-12-15 21:52:20,817] ERROR in app: Exception on /product/result [GET]
Traceback (most recent call last):
  File "/home/ec2-user/venv/lib64/python3.9/site-packages/flask/app.py", line 1455, in wsgi_app
    response = self.full_dispatch_request()
  File "/home/ec2-user/venv/lib64/python3.9/site-packages/flask/app.py", line 869, in full_dispatch_request
    rv = self.handle_user_exception(e)
  File "/home/ec2-user/venv/lib64/python3.9/site-packages/flask_cors/extension.py", line 176, in wrapped_function
    return cors_after_request(app.make_response(f(*args, **kwargs)))
  File "/home/ec2-user/venv/lib64/python3.9/site-packages/flask/app.py", line 867, in full_dispatch_request
    rv = self.dispatch_request()
  File "/home/ec2-user/venv/lib64/python3.9/site-packages/flask/app.py", line 852, in dispatch_request
    return self.ensure_sync(self.view_functions[rule.endpoint])(**view_args)
  File "/home/ec2-user/BluestPeakBackend/project/frameworks_and_drivers/controllers/product.py", line 26, in get_products
    product_dicts = interactor.execute(
  File "/home/ec2-user/BluestPeakBackend/project/use_cases/product_interactor.py", line 22, in execute
    product_dicts = self.product_dao.get_products(
  File "/home/ec2-user/BluestPeakBackend/project/interface_adapters/dao/productDao.py", line 19, in get_products
    product_list = [
  File "/home/ec2-user/BluestPeakBackend/project/interface_adapters/dao/productDao.py", line 19, in <listcomp>
    product_list = [
  File "/home/ec2-user/venv/lib64/python3.9/site-packages/pymongo/cursor.py", line 1176, in next
    if len(self.__data) or self._refresh():
  File "/home/ec2-user/venv/lib64/python3.9/site-packages/pymongo/cursor.py", line 1070, in _refresh
    self.__session = self.__collection.database.client._ensure_session()
  File "/home/ec2-user/venv/lib64/python3.9/site-packages/pymongo/mongo_client.py", line 1391, in _ensure_session
    return self.start_session(causal_consistency=False)
  File "/home/ec2-user/venv/lib64/python3.9/site-packages/pymongo/mongo_client.py", line 1369, in start_session
    server_session = self._get_server_session()
  File "/home/ec2-user/venv/lib64/python3.9/site-packages/pymongo/mongo_client.py", line 1377, in _get_server_session
    return self._topology.get_server_session()
  File "/home/ec2-user/venv/lib64/python3.9/site-packages/pymongo/topology.py", line 418, in get_server_session
    self._select_servers_loop(
  File "/home/ec2-user/venv/lib64/python3.9/site-packages/pymongo/topology.py", line 198, in _select_servers_loop
    raise ServerSelectionTimeoutError(
pymongo.errors.ServerSelectionTimeoutError: SSL handshake failed: [SSL: TLSV1_ALERT_INTERNAL_ERROR] tlsv1 alert internal error (_ssl.c:1129),SSL handshake failed: [SSL: TLSV1_ALERT_INTERNAL_ERROR] tlsv1 alert internal error (_ssl.c:1129),SSL handshake failed: [SSL: TLSV1_ALERT_INTERNAL_ERROR] tlsv1 alert internal error (_ssl.c:1129)
[2023-12-15 21:52:21 +0000] [138282] [CRITICAL] WORKER TIMEOUT (pid:138284)
[2023-12-15 21:52:21 +0000] [138284] [INFO] Worker exiting (pid: 138284)
[2023-12-15 21:52:21 +0000] [138282] [ERROR] Worker (pid:138284) exited with code 1
[2023-12-15 21:52:21 +0000] [138282] [ERROR] Worker (pid:138284) exited with code 1.
[2023-12-15 21:52:21 +0000] [138539] [INFO] Booting worker with pid: 138539
[2023-12-15 22:05:20,224] ERROR in app: Exception on /product/result [GET]
Traceback (most recent call last):
  File "/home/ec2-user/venv/lib64/python3.9/site-packages/flask/app.py", line 1455, in wsgi_app
    response = self.full_dispatch_request()
  File "/home/ec2-user/venv/lib64/python3.9/site-packages/flask/app.py", line 869, in full_dispatch_request
    rv = self.handle_user_exception(e)
  File "/home/ec2-user/venv/lib64/python3.9/site-packages/flask_cors/extension.py", line 176, in wrapped_function
    return cors_after_request(app.make_response(f(*args, **kwargs)))
  File "/home/ec2-user/venv/lib64/python3.9/site-packages/flask/app.py", line 867, in full_dispatch_request
    rv = self.dispatch_request()
  File "/home/ec2-user/venv/lib64/python3.9/site-packages/flask/app.py", line 852, in dispatch_request
    return self.ensure_sync(self.view_functions[rule.endpoint])(**view_args)
  File "/home/ec2-user/BluestPeakBackend/project/frameworks_and_drivers/controllers/product.py", line 26, in get_products
    product_dicts = interactor.execute(
  File "/home/ec2-user/BluestPeakBackend/project/use_cases/product_interactor.py", line 22, in execute
    product_dicts = self.product_dao.get_products(
  File "/home/ec2-user/BluestPeakBackend/project/interface_adapters/dao/productDao.py", line 19, in get_products
    product_list = [
  File "/home/ec2-user/BluestPeakBackend/project/interface_adapters/dao/productDao.py", line 19, in <listcomp>
    product_list = [
  File "/home/ec2-user/venv/lib64/python3.9/site-packages/pymongo/cursor.py", line 1176, in next
    if len(self.__data) or self._refresh():
  File "/home/ec2-user/venv/lib64/python3.9/site-packages/pymongo/cursor.py", line 1087, in _refresh
    self.__send_message(q)
  File "/home/ec2-user/venv/lib64/python3.9/site-packages/pymongo/cursor.py", line 923, in __send_message
    response = client._send_message_with_response(operation,
  File "/home/ec2-user/venv/lib64/python3.9/site-packages/pymongo/mongo_client.py", line 1019, in _send_message_with_response
    return self._reset_on_error(
  File "/home/ec2-user/venv/lib64/python3.9/site-packages/pymongo/mongo_client.py", line 1037, in _reset_on_error
    return func(*args, **kwargs)
  File "/home/ec2-user/venv/lib64/python3.9/site-packages/pymongo/server.py", line 85, in send_message_with_response
    with self.get_socket(all_credentials, exhaust) as sock_info:
  File "/usr/lib64/python3.9/contextlib.py", line 119, in __enter__
    return next(self.gen)
  File "/home/ec2-user/venv/lib64/python3.9/site-packages/pymongo/server.py", line 138, in get_socket
    with self.pool.get_socket(all_credentials, checkout) as sock_info:
  File "/usr/lib64/python3.9/contextlib.py", line 119, in __enter__
    return next(self.gen)
  File "/home/ec2-user/venv/lib64/python3.9/site-packages/pymongo/pool.py", line 893, in get_socket
    sock_info.check_auth(all_credentials)
  File "/home/ec2-user/venv/lib64/python3.9/site-packages/pymongo/pool.py", line 588, in check_auth
    auth.authenticate(credentials, self)
  File "/home/ec2-user/venv/lib64/python3.9/site-packages/pymongo/auth.py", line 486, in authenticate
    auth_func(credentials, sock_info)
  File "/home/ec2-user/venv/lib64/python3.9/site-packages/pymongo/auth.py", line 466, in _authenticate_default
    return _authenticate_scram_sha1(credentials, sock_info)
  File "/home/ec2-user/venv/lib64/python3.9/site-packages/pymongo/auth.py", line 237, in _authenticate_scram_sha1
    res = sock_info.command(source, cmd)
  File "/home/ec2-user/venv/lib64/python3.9/site-packages/pymongo/pool.py", line 490, in command
    return command(self.sock, dbname, spec, slave_ok,
  File "/home/ec2-user/venv/lib64/python3.9/site-packages/pymongo/network.py", line 123, in command
    helpers._check_command_response(
  File "/home/ec2-user/venv/lib64/python3.9/site-packages/pymongo/helpers.py", line 146, in _check_command_response
    raise OperationFailure(msg % errmsg, code, response)
pymongo.errors.OperationFailure: bad auth : authentication failed
[2023-12-15 22:05:20,237] ERROR in app: Request finalizing failed with an error while handling an error
Traceback (most recent call last):
  File "/home/ec2-user/venv/lib64/python3.9/site-packages/flask/app.py", line 1455, in wsgi_app
    response = self.full_dispatch_request()
  File "/home/ec2-user/venv/lib64/python3.9/site-packages/flask/app.py", line 869, in full_dispatch_request
    rv = self.handle_user_exception(e)
  File "/home/ec2-user/venv/lib64/python3.9/site-packages/flask_cors/extension.py", line 176, in wrapped_function
    return cors_after_request(app.make_response(f(*args, **kwargs)))
  File "/home/ec2-user/venv/lib64/python3.9/site-packages/flask/app.py", line 867, in full_dispatch_request
    rv = self.dispatch_request()
  File "/home/ec2-user/venv/lib64/python3.9/site-packages/flask/app.py", line 852, in dispatch_request
    return self.ensure_sync(self.view_functions[rule.endpoint])(**view_args)
  File "/home/ec2-user/BluestPeakBackend/project/frameworks_and_drivers/controllers/product.py", line 26, in get_products
    product_dicts = interactor.execute(
  File "/home/ec2-user/BluestPeakBackend/project/use_cases/product_interactor.py", line 22, in execute
    product_dicts = self.product_dao.get_products(
  File "/home/ec2-user/BluestPeakBackend/project/interface_adapters/dao/productDao.py", line 19, in get_products
    product_list = [
  File "/home/ec2-user/BluestPeakBackend/project/interface_adapters/dao/productDao.py", line 19, in <listcomp>
    product_list = [
  File "/home/ec2-user/venv/lib64/python3.9/site-packages/pymongo/cursor.py", line 1176, in next
    if len(self.__data) or self._refresh():
  File "/home/ec2-user/venv/lib64/python3.9/site-packages/pymongo/cursor.py", line 1087, in _refresh
    self.__send_message(q)
  File "/home/ec2-user/venv/lib64/python3.9/site-packages/pymongo/cursor.py", line 923, in __send_message
    response = client._send_message_with_response(operation,
  File "/home/ec2-user/venv/lib64/python3.9/site-packages/pymongo/mongo_client.py", line 1019, in _send_message_with_response
    return self._reset_on_error(
  File "/home/ec2-user/venv/lib64/python3.9/site-packages/pymongo/mongo_client.py", line 1037, in _reset_on_error
    return func(*args, **kwargs)
  File "/home/ec2-user/venv/lib64/python3.9/site-packages/pymongo/server.py", line 85, in send_message_with_response
    with self.get_socket(all_credentials, exhaust) as sock_info:
  File "/usr/lib64/python3.9/contextlib.py", line 119, in __enter__
    return next(self.gen)
  File "/home/ec2-user/venv/lib64/python3.9/site-packages/pymongo/server.py", line 138, in get_socket
    with self.pool.get_socket(all_credentials, checkout) as sock_info:
  File "/usr/lib64/python3.9/contextlib.py", line 119, in __enter__
    return next(self.gen)
  File "/home/ec2-user/venv/lib64/python3.9/site-packages/pymongo/pool.py", line 893, in get_socket
    sock_info.check_auth(all_credentials)
  File "/home/ec2-user/venv/lib64/python3.9/site-packages/pymongo/pool.py", line 588, in check_auth
    auth.authenticate(credentials, self)
  File "/home/ec2-user/venv/lib64/python3.9/site-packages/pymongo/auth.py", line 486, in authenticate
    auth_func(credentials, sock_info)
  File "/home/ec2-user/venv/lib64/python3.9/site-packages/pymongo/auth.py", line 466, in _authenticate_default
    return _authenticate_scram_sha1(credentials, sock_info)
  File "/home/ec2-user/venv/lib64/python3.9/site-packages/pymongo/auth.py", line 237, in _authenticate_scram_sha1
    res = sock_info.command(source, cmd)
  File "/home/ec2-user/venv/lib64/python3.9/site-packages/pymongo/pool.py", line 490, in command
    return command(self.sock, dbname, spec, slave_ok,
  File "/home/ec2-user/venv/lib64/python3.9/site-packages/pymongo/network.py", line 123, in command
    helpers._check_command_response(
  File "/home/ec2-user/venv/lib64/python3.9/site-packages/pymongo/helpers.py", line 146, in _check_command_response
    raise OperationFailure(msg % errmsg, code, response)
pymongo.errors.OperationFailure: bad auth : authentication failed

During handling of the above exception, another exception occurred:

Traceback (most recent call last):
  File "/home/ec2-user/venv/lib64/python3.9/site-packages/flask/app.py", line 891, in finalize_request
    response = self.process_response(response)
  File "/home/ec2-user/venv/lib64/python3.9/site-packages/flask/app.py", line 1267, in process_response
    response = self.ensure_sync(func)(response)
  File "/home/ec2-user/BluestPeakBackend/project/frameworks_and_drivers/app.py", line 85, in after_request
    if not EnterpriseDao.enterprise_has_paid(enterprise_id):
  File "/home/ec2-user/BluestPeakBackend/project/interface_adapters/dao/enterpriseDao.py", line 64, in enterprise_has_paid
    enterprise = enterprises.find_one({'_id':enterprise_id})
  File "/home/ec2-user/venv/lib64/python3.9/site-packages/pymongo/collection.py", line 1224, in find_one
    for result in cursor.limit(-1):
  File "/home/ec2-user/venv/lib64/python3.9/site-packages/pymongo/cursor.py", line 1176, in next
    if len(self.__data) or self._refresh():
  File "/home/ec2-user/venv/lib64/python3.9/site-packages/pymongo/cursor.py", line 1087, in _refresh
    self.__send_message(q)
  File "/home/ec2-user/venv/lib64/python3.9/site-packages/pymongo/cursor.py", line 923, in __send_message
    response = client._send_message_with_response(operation,
  File "/home/ec2-user/venv/lib64/python3.9/site-packages/pymongo/mongo_client.py", line 1019, in _send_message_with_response
    return self._reset_on_error(
  File "/home/ec2-user/venv/lib64/python3.9/site-packages/pymongo/mongo_client.py", line 1037, in _reset_on_error
    return func(*args, **kwargs)
  File "/home/ec2-user/venv/lib64/python3.9/site-packages/pymongo/server.py", line 85, in send_message_with_response
    with self.get_socket(all_credentials, exhaust) as sock_info:
  File "/usr/lib64/python3.9/contextlib.py", line 119, in __enter__
    return next(self.gen)
  File "/home/ec2-user/venv/lib64/python3.9/site-packages/pymongo/server.py", line 138, in get_socket
    with self.pool.get_socket(all_credentials, checkout) as sock_info:
  File "/usr/lib64/python3.9/contextlib.py", line 119, in __enter__
    return next(self.gen)
  File "/home/ec2-user/venv/lib64/python3.9/site-packages/pymongo/pool.py", line 893, in get_socket
    sock_info.check_auth(all_credentials)
  File "/home/ec2-user/venv/lib64/python3.9/site-packages/pymongo/pool.py", line 588, in check_auth
    auth.authenticate(credentials, self)
  File "/home/ec2-user/venv/lib64/python3.9/site-packages/pymongo/auth.py", line 486, in authenticate
    auth_func(credentials, sock_info)
  File "/home/ec2-user/venv/lib64/python3.9/site-packages/pymongo/auth.py", line 466, in _authenticate_default
    return _authenticate_scram_sha1(credentials, sock_info)
  File "/home/ec2-user/venv/lib64/python3.9/site-packages/pymongo/auth.py", line 237, in _authenticate_scram_sha1
    res = sock_info.command(source, cmd)
  File "/home/ec2-user/venv/lib64/python3.9/site-packages/pymongo/pool.py", line 490, in command
    return command(self.sock, dbname, spec, slave_ok,
  File "/home/ec2-user/venv/lib64/python3.9/site-packages/pymongo/network.py", line 123, in command
    helpers._check_command_response(
  File "/home/ec2-user/venv/lib64/python3.9/site-packages/pymongo/helpers.py", line 146, in _check_command_response
    raise OperationFailure(msg % errmsg, code, response)
pymongo.errors.OperationFailure: bad auth : authentication failed
[2023-12-15 22:05:51,295] ERROR in app: Exception on /product/result [GET]
Traceback (most recent call last):
  File "/home/ec2-user/venv/lib64/python3.9/site-packages/flask/app.py", line 1455, in wsgi_app
    response = self.full_dispatch_request()
  File "/home/ec2-user/venv/lib64/python3.9/site-packages/flask/app.py", line 869, in full_dispatch_request
    rv = self.handle_user_exception(e)
  File "/home/ec2-user/venv/lib64/python3.9/site-packages/flask_cors/extension.py", line 176, in wrapped_function
    return cors_after_request(app.make_response(f(*args, **kwargs)))
  File "/home/ec2-user/venv/lib64/python3.9/site-packages/flask/app.py", line 867, in full_dispatch_request
    rv = self.dispatch_request()
  File "/home/ec2-user/venv/lib64/python3.9/site-packages/flask/app.py", line 852, in dispatch_request
    return self.ensure_sync(self.view_functions[rule.endpoint])(**view_args)
  File "/home/ec2-user/BluestPeakBackend/project/frameworks_and_drivers/controllers/product.py", line 26, in get_products
    product_dicts = interactor.execute(
  File "/home/ec2-user/BluestPeakBackend/project/use_cases/product_interactor.py", line 22, in execute
    product_dicts = self.product_dao.get_products(
  File "/home/ec2-user/BluestPeakBackend/project/interface_adapters/dao/productDao.py", line 19, in get_products
    product_list = [
  File "/home/ec2-user/BluestPeakBackend/project/interface_adapters/dao/productDao.py", line 19, in <listcomp>
    product_list = [
  File "/home/ec2-user/venv/lib64/python3.9/site-packages/pymongo/cursor.py", line 1176, in next
    if len(self.__data) or self._refresh():
  File "/home/ec2-user/venv/lib64/python3.9/site-packages/pymongo/cursor.py", line 1087, in _refresh
    self.__send_message(q)
  File "/home/ec2-user/venv/lib64/python3.9/site-packages/pymongo/cursor.py", line 923, in __send_message
    response = client._send_message_with_response(operation,
  File "/home/ec2-user/venv/lib64/python3.9/site-packages/pymongo/mongo_client.py", line 1019, in _send_message_with_response
    return self._reset_on_error(
  File "/home/ec2-user/venv/lib64/python3.9/site-packages/pymongo/mongo_client.py", line 1037, in _reset_on_error
    return func(*args, **kwargs)
  File "/home/ec2-user/venv/lib64/python3.9/site-packages/pymongo/server.py", line 85, in send_message_with_response
    with self.get_socket(all_credentials, exhaust) as sock_info:
  File "/usr/lib64/python3.9/contextlib.py", line 119, in __enter__
    return next(self.gen)
  File "/home/ec2-user/venv/lib64/python3.9/site-packages/pymongo/server.py", line 138, in get_socket
    with self.pool.get_socket(all_credentials, checkout) as sock_info:
  File "/usr/lib64/python3.9/contextlib.py", line 119, in __enter__
    return next(self.gen)
  File "/home/ec2-user/venv/lib64/python3.9/site-packages/pymongo/pool.py", line 893, in get_socket
    sock_info.check_auth(all_credentials)
  File "/home/ec2-user/venv/lib64/python3.9/site-packages/pymongo/pool.py", line 588, in check_auth
    auth.authenticate(credentials, self)
  File "/home/ec2-user/venv/lib64/python3.9/site-packages/pymongo/auth.py", line 486, in authenticate
    auth_func(credentials, sock_info)
  File "/home/ec2-user/venv/lib64/python3.9/site-packages/pymongo/auth.py", line 466, in _authenticate_default
    return _authenticate_scram_sha1(credentials, sock_info)
  File "/home/ec2-user/venv/lib64/python3.9/site-packages/pymongo/auth.py", line 237, in _authenticate_scram_sha1
    res = sock_info.command(source, cmd)
  File "/home/ec2-user/venv/lib64/python3.9/site-packages/pymongo/pool.py", line 490, in command
    return command(self.sock, dbname, spec, slave_ok,
  File "/home/ec2-user/venv/lib64/python3.9/site-packages/pymongo/network.py", line 123, in command
    helpers._check_command_response(
  File "/home/ec2-user/venv/lib64/python3.9/site-packages/pymongo/helpers.py", line 146, in _check_command_response
    raise OperationFailure(msg % errmsg, code, response)
pymongo.errors.OperationFailure: bad auth : authentication failed
[2023-12-15 22:05:51,306] ERROR in app: Request finalizing failed with an error while handling an error
Traceback (most recent call last):
  File "/home/ec2-user/venv/lib64/python3.9/site-packages/flask/app.py", line 1455, in wsgi_app
    response = self.full_dispatch_request()
  File "/home/ec2-user/venv/lib64/python3.9/site-packages/flask/app.py", line 869, in full_dispatch_request
    rv = self.handle_user_exception(e)
  File "/home/ec2-user/venv/lib64/python3.9/site-packages/flask_cors/extension.py", line 176, in wrapped_function
    return cors_after_request(app.make_response(f(*args, **kwargs)))
  File "/home/ec2-user/venv/lib64/python3.9/site-packages/flask/app.py", line 867, in full_dispatch_request
    rv = self.dispatch_request()
  File "/home/ec2-user/venv/lib64/python3.9/site-packages/flask/app.py", line 852, in dispatch_request
    return self.ensure_sync(self.view_functions[rule.endpoint])(**view_args)
  File "/home/ec2-user/BluestPeakBackend/project/frameworks_and_drivers/controllers/product.py", line 26, in get_products
    product_dicts = interactor.execute(
  File "/home/ec2-user/BluestPeakBackend/project/use_cases/product_interactor.py", line 22, in execute
    product_dicts = self.product_dao.get_products(
  File "/home/ec2-user/BluestPeakBackend/project/interface_adapters/dao/productDao.py", line 19, in get_products
    product_list = [
  File "/home/ec2-user/BluestPeakBackend/project/interface_adapters/dao/productDao.py", line 19, in <listcomp>
    product_list = [
  File "/home/ec2-user/venv/lib64/python3.9/site-packages/pymongo/cursor.py", line 1176, in next
    if len(self.__data) or self._refresh():
  File "/home/ec2-user/venv/lib64/python3.9/site-packages/pymongo/cursor.py", line 1087, in _refresh
    self.__send_message(q)
  File "/home/ec2-user/venv/lib64/python3.9/site-packages/pymongo/cursor.py", line 923, in __send_message
    response = client._send_message_with_response(operation,
  File "/home/ec2-user/venv/lib64/python3.9/site-packages/pymongo/mongo_client.py", line 1019, in _send_message_with_response
    return self._reset_on_error(
  File "/home/ec2-user/venv/lib64/python3.9/site-packages/pymongo/mongo_client.py", line 1037, in _reset_on_error
    return func(*args, **kwargs)
  File "/home/ec2-user/venv/lib64/python3.9/site-packages/pymongo/server.py", line 85, in send_message_with_response
    with self.get_socket(all_credentials, exhaust) as sock_info:
  File "/usr/lib64/python3.9/contextlib.py", line 119, in __enter__
    return next(self.gen)
  File "/home/ec2-user/venv/lib64/python3.9/site-packages/pymongo/server.py", line 138, in get_socket
    with self.pool.get_socket(all_credentials, checkout) as sock_info:
  File "/usr/lib64/python3.9/contextlib.py", line 119, in __enter__
    return next(self.gen)
  File "/home/ec2-user/venv/lib64/python3.9/site-packages/pymongo/pool.py", line 893, in get_socket
    sock_info.check_auth(all_credentials)
  File "/home/ec2-user/venv/lib64/python3.9/site-packages/pymongo/pool.py", line 588, in check_auth
    auth.authenticate(credentials, self)
  File "/home/ec2-user/venv/lib64/python3.9/site-packages/pymongo/auth.py", line 486, in authenticate
    auth_func(credentials, sock_info)
  File "/home/ec2-user/venv/lib64/python3.9/site-packages/pymongo/auth.py", line 466, in _authenticate_default
    return _authenticate_scram_sha1(credentials, sock_info)
  File "/home/ec2-user/venv/lib64/python3.9/site-packages/pymongo/auth.py", line 237, in _authenticate_scram_sha1
    res = sock_info.command(source, cmd)
  File "/home/ec2-user/venv/lib64/python3.9/site-packages/pymongo/pool.py", line 490, in command
    return command(self.sock, dbname, spec, slave_ok,
  File "/home/ec2-user/venv/lib64/python3.9/site-packages/pymongo/network.py", line 123, in command
    helpers._check_command_response(
  File "/home/ec2-user/venv/lib64/python3.9/site-packages/pymongo/helpers.py", line 146, in _check_command_response
    raise OperationFailure(msg % errmsg, code, response)
pymongo.errors.OperationFailure: bad auth : authentication failed

During handling of the above exception, another exception occurred:

Traceback (most recent call last):
  File "/home/ec2-user/venv/lib64/python3.9/site-packages/flask/app.py", line 891, in finalize_request
    response = self.process_response(response)
  File "/home/ec2-user/venv/lib64/python3.9/site-packages/flask/app.py", line 1267, in process_response
    response = self.ensure_sync(func)(response)
  File "/home/ec2-user/BluestPeakBackend/project/frameworks_and_drivers/app.py", line 85, in after_request
    if not EnterpriseDao.enterprise_has_paid(enterprise_id):
  File "/home/ec2-user/BluestPeakBackend/project/interface_adapters/dao/enterpriseDao.py", line 64, in enterprise_has_paid
    enterprise = enterprises.find_one({'_id':enterprise_id})
  File "/home/ec2-user/venv/lib64/python3.9/site-packages/pymongo/collection.py", line 1224, in find_one
    for result in cursor.limit(-1):
  File "/home/ec2-user/venv/lib64/python3.9/site-packages/pymongo/cursor.py", line 1176, in next
    if len(self.__data) or self._refresh():
  File "/home/ec2-user/venv/lib64/python3.9/site-packages/pymongo/cursor.py", line 1087, in _refresh
    self.__send_message(q)
  File "/home/ec2-user/venv/lib64/python3.9/site-packages/pymongo/cursor.py", line 923, in __send_message
    response = client._send_message_with_response(operation,
  File "/home/ec2-user/venv/lib64/python3.9/site-packages/pymongo/mongo_client.py", line 1019, in _send_message_with_response
    return self._reset_on_error(
  File "/home/ec2-user/venv/lib64/python3.9/site-packages/pymongo/mongo_client.py", line 1037, in _reset_on_error
    return func(*args, **kwargs)
  File "/home/ec2-user/venv/lib64/python3.9/site-packages/pymongo/server.py", line 85, in send_message_with_response
    with self.get_socket(all_credentials, exhaust) as sock_info:
  File "/usr/lib64/python3.9/contextlib.py", line 119, in __enter__
    return next(self.gen)
  File "/home/ec2-user/venv/lib64/python3.9/site-packages/pymongo/server.py", line 138, in get_socket
    with self.pool.get_socket(all_credentials, checkout) as sock_info:
  File "/usr/lib64/python3.9/contextlib.py", line 119, in __enter__
    return next(self.gen)
  File "/home/ec2-user/venv/lib64/python3.9/site-packages/pymongo/pool.py", line 893, in get_socket
    sock_info.check_auth(all_credentials)
  File "/home/ec2-user/venv/lib64/python3.9/site-packages/pymongo/pool.py", line 588, in check_auth
    auth.authenticate(credentials, self)
  File "/home/ec2-user/venv/lib64/python3.9/site-packages/pymongo/auth.py", line 486, in authenticate
    auth_func(credentials, sock_info)
  File "/home/ec2-user/venv/lib64/python3.9/site-packages/pymongo/auth.py", line 466, in _authenticate_default
    return _authenticate_scram_sha1(credentials, sock_info)
  File "/home/ec2-user/venv/lib64/python3.9/site-packages/pymongo/auth.py", line 237, in _authenticate_scram_sha1
    res = sock_info.command(source, cmd)
  File "/home/ec2-user/venv/lib64/python3.9/site-packages/pymongo/pool.py", line 490, in command
    return command(self.sock, dbname, spec, slave_ok,
  File "/home/ec2-user/venv/lib64/python3.9/site-packages/pymongo/network.py", line 123, in command
    helpers._check_command_response(
  File "/home/ec2-user/venv/lib64/python3.9/site-packages/pymongo/helpers.py", line 146, in _check_command_response
    raise OperationFailure(msg % errmsg, code, response)
pymongo.errors.OperationFailure: bad auth : authentication failed
[2023-12-15 22:14:29 +0000] [138282] [INFO] Handling signal: term
[2023-12-15 22:14:29 +0000] [138285] [INFO] Worker exiting (pid: 138285)
[2023-12-15 22:14:29 +0000] [138527] [INFO] Worker exiting (pid: 138527)
[2023-12-15 22:14:29 +0000] [138539] [INFO] Worker exiting (pid: 138539)
[2023-12-15 22:14:30 +0000] [138282] [INFO] Shutting down: Master
[2023-12-15 22:14:30 +0000] [139262] [INFO] Starting gunicorn 21.2.0
[2023-12-15 22:14:30 +0000] [139262] [INFO] Listening at: http://0.0.0.0:8000 (139262)
[2023-12-15 22:14:30 +0000] [139262] [INFO] Using worker: sync
[2023-12-15 22:14:30 +0000] [139264] [INFO] Booting worker with pid: 139264
[2023-12-15 22:14:30 +0000] [139265] [INFO] Booting worker with pid: 139265
[2023-12-15 22:14:30 +0000] [139266] [INFO] Booting worker with pid: 139266
[2023-12-15 22:15:26,027] ERROR in app: Exception on /product/result [GET]
Traceback (most recent call last):
  File "/home/ec2-user/venv/lib64/python3.9/site-packages/flask/app.py", line 1455, in wsgi_app
    response = self.full_dispatch_request()
  File "/home/ec2-user/venv/lib64/python3.9/site-packages/flask/app.py", line 869, in full_dispatch_request
    rv = self.handle_user_exception(e)
  File "/home/ec2-user/venv/lib64/python3.9/site-packages/flask_cors/extension.py", line 176, in wrapped_function
    return cors_after_request(app.make_response(f(*args, **kwargs)))
  File "/home/ec2-user/venv/lib64/python3.9/site-packages/flask/app.py", line 867, in full_dispatch_request
    rv = self.dispatch_request()
  File "/home/ec2-user/venv/lib64/python3.9/site-packages/flask/app.py", line 852, in dispatch_request
    return self.ensure_sync(self.view_functions[rule.endpoint])(**view_args)
  File "/home/ec2-user/BluestPeakBackend/project/frameworks_and_drivers/controllers/product.py", line 26, in get_products
    product_dicts = interactor.execute(
  File "/home/ec2-user/BluestPeakBackend/project/use_cases/product_interactor.py", line 22, in execute
    product_dicts = self.product_dao.get_products(
  File "/home/ec2-user/BluestPeakBackend/project/interface_adapters/dao/productDao.py", line 19, in get_products
    product_list = [
  File "/home/ec2-user/BluestPeakBackend/project/interface_adapters/dao/productDao.py", line 19, in <listcomp>
    product_list = [
  File "/home/ec2-user/venv/lib64/python3.9/site-packages/pymongo/cursor.py", line 1176, in next
    if len(self.__data) or self._refresh():
  File "/home/ec2-user/venv/lib64/python3.9/site-packages/pymongo/cursor.py", line 1087, in _refresh
    self.__send_message(q)
  File "/home/ec2-user/venv/lib64/python3.9/site-packages/pymongo/cursor.py", line 923, in __send_message
    response = client._send_message_with_response(operation,
  File "/home/ec2-user/venv/lib64/python3.9/site-packages/pymongo/mongo_client.py", line 1019, in _send_message_with_response
    return self._reset_on_error(
  File "/home/ec2-user/venv/lib64/python3.9/site-packages/pymongo/mongo_client.py", line 1037, in _reset_on_error
    return func(*args, **kwargs)
  File "/home/ec2-user/venv/lib64/python3.9/site-packages/pymongo/server.py", line 85, in send_message_with_response
    with self.get_socket(all_credentials, exhaust) as sock_info:
  File "/usr/lib64/python3.9/contextlib.py", line 119, in __enter__
    return next(self.gen)
  File "/home/ec2-user/venv/lib64/python3.9/site-packages/pymongo/server.py", line 138, in get_socket
    with self.pool.get_socket(all_credentials, checkout) as sock_info:
  File "/usr/lib64/python3.9/contextlib.py", line 119, in __enter__
    return next(self.gen)
  File "/home/ec2-user/venv/lib64/python3.9/site-packages/pymongo/pool.py", line 893, in get_socket
    sock_info.check_auth(all_credentials)
  File "/home/ec2-user/venv/lib64/python3.9/site-packages/pymongo/pool.py", line 588, in check_auth
    auth.authenticate(credentials, self)
  File "/home/ec2-user/venv/lib64/python3.9/site-packages/pymongo/auth.py", line 486, in authenticate
    auth_func(credentials, sock_info)
  File "/home/ec2-user/venv/lib64/python3.9/site-packages/pymongo/auth.py", line 466, in _authenticate_default
    return _authenticate_scram_sha1(credentials, sock_info)
  File "/home/ec2-user/venv/lib64/python3.9/site-packages/pymongo/auth.py", line 237, in _authenticate_scram_sha1
    res = sock_info.command(source, cmd)
  File "/home/ec2-user/venv/lib64/python3.9/site-packages/pymongo/pool.py", line 490, in command
    return command(self.sock, dbname, spec, slave_ok,
  File "/home/ec2-user/venv/lib64/python3.9/site-packages/pymongo/network.py", line 123, in command
    helpers._check_command_response(
  File "/home/ec2-user/venv/lib64/python3.9/site-packages/pymongo/helpers.py", line 146, in _check_command_response
    raise OperationFailure(msg % errmsg, code, response)
pymongo.errors.OperationFailure: bad auth : authentication failed
[2023-12-15 22:15:26,039] ERROR in app: Request finalizing failed with an error while handling an error
Traceback (most recent call last):
  File "/home/ec2-user/venv/lib64/python3.9/site-packages/flask/app.py", line 1455, in wsgi_app
    response = self.full_dispatch_request()
  File "/home/ec2-user/venv/lib64/python3.9/site-packages/flask/app.py", line 869, in full_dispatch_request
    rv = self.handle_user_exception(e)
  File "/home/ec2-user/venv/lib64/python3.9/site-packages/flask_cors/extension.py", line 176, in wrapped_function
    return cors_after_request(app.make_response(f(*args, **kwargs)))
  File "/home/ec2-user/venv/lib64/python3.9/site-packages/flask/app.py", line 867, in full_dispatch_request
    rv = self.dispatch_request()
  File "/home/ec2-user/venv/lib64/python3.9/site-packages/flask/app.py", line 852, in dispatch_request
    return self.ensure_sync(self.view_functions[rule.endpoint])(**view_args)
  File "/home/ec2-user/BluestPeakBackend/project/frameworks_and_drivers/controllers/product.py", line 26, in get_products
    product_dicts = interactor.execute(
  File "/home/ec2-user/BluestPeakBackend/project/use_cases/product_interactor.py", line 22, in execute
    product_dicts = self.product_dao.get_products(
  File "/home/ec2-user/BluestPeakBackend/project/interface_adapters/dao/productDao.py", line 19, in get_products
    product_list = [
  File "/home/ec2-user/BluestPeakBackend/project/interface_adapters/dao/productDao.py", line 19, in <listcomp>
    product_list = [
  File "/home/ec2-user/venv/lib64/python3.9/site-packages/pymongo/cursor.py", line 1176, in next
    if len(self.__data) or self._refresh():
  File "/home/ec2-user/venv/lib64/python3.9/site-packages/pymongo/cursor.py", line 1087, in _refresh
    self.__send_message(q)
  File "/home/ec2-user/venv/lib64/python3.9/site-packages/pymongo/cursor.py", line 923, in __send_message
    response = client._send_message_with_response(operation,
  File "/home/ec2-user/venv/lib64/python3.9/site-packages/pymongo/mongo_client.py", line 1019, in _send_message_with_response
    return self._reset_on_error(
  File "/home/ec2-user/venv/lib64/python3.9/site-packages/pymongo/mongo_client.py", line 1037, in _reset_on_error
    return func(*args, **kwargs)
  File "/home/ec2-user/venv/lib64/python3.9/site-packages/pymongo/server.py", line 85, in send_message_with_response
    with self.get_socket(all_credentials, exhaust) as sock_info:
  File "/usr/lib64/python3.9/contextlib.py", line 119, in __enter__
    return next(self.gen)
  File "/home/ec2-user/venv/lib64/python3.9/site-packages/pymongo/server.py", line 138, in get_socket
    with self.pool.get_socket(all_credentials, checkout) as sock_info:
  File "/usr/lib64/python3.9/contextlib.py", line 119, in __enter__
    return next(self.gen)
  File "/home/ec2-user/venv/lib64/python3.9/site-packages/pymongo/pool.py", line 893, in get_socket
    sock_info.check_auth(all_credentials)
  File "/home/ec2-user/venv/lib64/python3.9/site-packages/pymongo/pool.py", line 588, in check_auth
    auth.authenticate(credentials, self)
  File "/home/ec2-user/venv/lib64/python3.9/site-packages/pymongo/auth.py", line 486, in authenticate
    auth_func(credentials, sock_info)
  File "/home/ec2-user/venv/lib64/python3.9/site-packages/pymongo/auth.py", line 466, in _authenticate_default
    return _authenticate_scram_sha1(credentials, sock_info)
  File "/home/ec2-user/venv/lib64/python3.9/site-packages/pymongo/auth.py", line 237, in _authenticate_scram_sha1
    res = sock_info.command(source, cmd)
  File "/home/ec2-user/venv/lib64/python3.9/site-packages/pymongo/pool.py", line 490, in command
    return command(self.sock, dbname, spec, slave_ok,
  File "/home/ec2-user/venv/lib64/python3.9/site-packages/pymongo/network.py", line 123, in command
    helpers._check_command_response(
  File "/home/ec2-user/venv/lib64/python3.9/site-packages/pymongo/helpers.py", line 146, in _check_command_response
    raise OperationFailure(msg % errmsg, code, response)
pymongo.errors.OperationFailure: bad auth : authentication failed

During handling of the above exception, another exception occurred:

Traceback (most recent call last):
  File "/home/ec2-user/venv/lib64/python3.9/site-packages/flask/app.py", line 891, in finalize_request
    response = self.process_response(response)
  File "/home/ec2-user/venv/lib64/python3.9/site-packages/flask/app.py", line 1267, in process_response
    response = self.ensure_sync(func)(response)
  File "/home/ec2-user/BluestPeakBackend/project/frameworks_and_drivers/app.py", line 85, in after_request
    if not EnterpriseDao.enterprise_has_paid(enterprise_id):
  File "/home/ec2-user/BluestPeakBackend/project/interface_adapters/dao/enterpriseDao.py", line 64, in enterprise_has_paid
    enterprise = enterprises.find_one({'_id':enterprise_id})
  File "/home/ec2-user/venv/lib64/python3.9/site-packages/pymongo/collection.py", line 1224, in find_one
    for result in cursor.limit(-1):
  File "/home/ec2-user/venv/lib64/python3.9/site-packages/pymongo/cursor.py", line 1176, in next
    if len(self.__data) or self._refresh():
  File "/home/ec2-user/venv/lib64/python3.9/site-packages/pymongo/cursor.py", line 1087, in _refresh
    self.__send_message(q)
  File "/home/ec2-user/venv/lib64/python3.9/site-packages/pymongo/cursor.py", line 923, in __send_message
    response = client._send_message_with_response(operation,
  File "/home/ec2-user/venv/lib64/python3.9/site-packages/pymongo/mongo_client.py", line 1019, in _send_message_with_response
    return self._reset_on_error(
  File "/home/ec2-user/venv/lib64/python3.9/site-packages/pymongo/mongo_client.py", line 1037, in _reset_on_error
    return func(*args, **kwargs)
  File "/home/ec2-user/venv/lib64/python3.9/site-packages/pymongo/server.py", line 85, in send_message_with_response
    with self.get_socket(all_credentials, exhaust) as sock_info:
  File "/usr/lib64/python3.9/contextlib.py", line 119, in __enter__
    return next(self.gen)
  File "/home/ec2-user/venv/lib64/python3.9/site-packages/pymongo/server.py", line 138, in get_socket
    with self.pool.get_socket(all_credentials, checkout) as sock_info:
  File "/usr/lib64/python3.9/contextlib.py", line 119, in __enter__
    return next(self.gen)
  File "/home/ec2-user/venv/lib64/python3.9/site-packages/pymongo/pool.py", line 893, in get_socket
    sock_info.check_auth(all_credentials)
  File "/home/ec2-user/venv/lib64/python3.9/site-packages/pymongo/pool.py", line 588, in check_auth
    auth.authenticate(credentials, self)
  File "/home/ec2-user/venv/lib64/python3.9/site-packages/pymongo/auth.py", line 486, in authenticate
    auth_func(credentials, sock_info)
  File "/home/ec2-user/venv/lib64/python3.9/site-packages/pymongo/auth.py", line 466, in _authenticate_default
    return _authenticate_scram_sha1(credentials, sock_info)
  File "/home/ec2-user/venv/lib64/python3.9/site-packages/pymongo/auth.py", line 237, in _authenticate_scram_sha1
    res = sock_info.command(source, cmd)
  File "/home/ec2-user/venv/lib64/python3.9/site-packages/pymongo/pool.py", line 490, in command
    return command(self.sock, dbname, spec, slave_ok,
  File "/home/ec2-user/venv/lib64/python3.9/site-packages/pymongo/network.py", line 123, in command
    helpers._check_command_response(
  File "/home/ec2-user/venv/lib64/python3.9/site-packages/pymongo/helpers.py", line 146, in _check_command_response
    raise OperationFailure(msg % errmsg, code, response)
pymongo.errors.OperationFailure: bad auth : authentication failed
[2023-12-15 22:18:16 +0000] [139262] [INFO] Handling signal: term
[2023-12-15 22:18:16 +0000] [139264] [INFO] Worker exiting (pid: 139264)
[2023-12-15 22:18:16 +0000] [139265] [INFO] Worker exiting (pid: 139265)
[2023-12-15 22:18:16 +0000] [139266] [INFO] Worker exiting (pid: 139266)
[2023-12-15 22:18:17 +0000] [139262] [INFO] Shutting down: Master
[2023-12-15 22:18:17 +0000] [139479] [INFO] Starting gunicorn 21.2.0
[2023-12-15 22:18:17 +0000] [139479] [INFO] Listening at: http://0.0.0.0:8000 (139479)
[2023-12-15 22:18:17 +0000] [139479] [INFO] Using worker: sync
[2023-12-15 22:18:17 +0000] [139480] [INFO] Booting worker with pid: 139480
[2023-12-15 22:18:17 +0000] [139481] [INFO] Booting worker with pid: 139481
[2023-12-15 22:18:17 +0000] [139482] [INFO] Booting worker with pid: 139482
[2023-12-15 22:18:27,040] ERROR in app: Exception on /product/result [GET]
Traceback (most recent call last):
  File "/home/ec2-user/venv/lib64/python3.9/site-packages/flask/app.py", line 1455, in wsgi_app
    response = self.full_dispatch_request()
  File "/home/ec2-user/venv/lib64/python3.9/site-packages/flask/app.py", line 869, in full_dispatch_request
    rv = self.handle_user_exception(e)
  File "/home/ec2-user/venv/lib64/python3.9/site-packages/flask_cors/extension.py", line 176, in wrapped_function
    return cors_after_request(app.make_response(f(*args, **kwargs)))
  File "/home/ec2-user/venv/lib64/python3.9/site-packages/flask/app.py", line 867, in full_dispatch_request
    rv = self.dispatch_request()
  File "/home/ec2-user/venv/lib64/python3.9/site-packages/flask/app.py", line 852, in dispatch_request
    return self.ensure_sync(self.view_functions[rule.endpoint])(**view_args)
  File "/home/ec2-user/BluestPeakBackend/project/frameworks_and_drivers/controllers/product.py", line 26, in get_products
    product_dicts = interactor.execute(
  File "/home/ec2-user/BluestPeakBackend/project/use_cases/product_interactor.py", line 22, in execute
    product_dicts = self.product_dao.get_products(
  File "/home/ec2-user/BluestPeakBackend/project/interface_adapters/dao/productDao.py", line 19, in get_products
    product_list = [
  File "/home/ec2-user/BluestPeakBackend/project/interface_adapters/dao/productDao.py", line 19, in <listcomp>
    product_list = [
  File "/home/ec2-user/venv/lib64/python3.9/site-packages/pymongo/cursor.py", line 1176, in next
    if len(self.__data) or self._refresh():
  File "/home/ec2-user/venv/lib64/python3.9/site-packages/pymongo/cursor.py", line 1087, in _refresh
    self.__send_message(q)
  File "/home/ec2-user/venv/lib64/python3.9/site-packages/pymongo/cursor.py", line 923, in __send_message
    response = client._send_message_with_response(operation,
  File "/home/ec2-user/venv/lib64/python3.9/site-packages/pymongo/mongo_client.py", line 1019, in _send_message_with_response
    return self._reset_on_error(
  File "/home/ec2-user/venv/lib64/python3.9/site-packages/pymongo/mongo_client.py", line 1037, in _reset_on_error
    return func(*args, **kwargs)
  File "/home/ec2-user/venv/lib64/python3.9/site-packages/pymongo/server.py", line 85, in send_message_with_response
    with self.get_socket(all_credentials, exhaust) as sock_info:
  File "/usr/lib64/python3.9/contextlib.py", line 119, in __enter__
    return next(self.gen)
  File "/home/ec2-user/venv/lib64/python3.9/site-packages/pymongo/server.py", line 138, in get_socket
    with self.pool.get_socket(all_credentials, checkout) as sock_info:
  File "/usr/lib64/python3.9/contextlib.py", line 119, in __enter__
    return next(self.gen)
  File "/home/ec2-user/venv/lib64/python3.9/site-packages/pymongo/pool.py", line 893, in get_socket
    sock_info.check_auth(all_credentials)
  File "/home/ec2-user/venv/lib64/python3.9/site-packages/pymongo/pool.py", line 588, in check_auth
    auth.authenticate(credentials, self)
  File "/home/ec2-user/venv/lib64/python3.9/site-packages/pymongo/auth.py", line 486, in authenticate
    auth_func(credentials, sock_info)
  File "/home/ec2-user/venv/lib64/python3.9/site-packages/pymongo/auth.py", line 466, in _authenticate_default
    return _authenticate_scram_sha1(credentials, sock_info)
  File "/home/ec2-user/venv/lib64/python3.9/site-packages/pymongo/auth.py", line 237, in _authenticate_scram_sha1
    res = sock_info.command(source, cmd)
  File "/home/ec2-user/venv/lib64/python3.9/site-packages/pymongo/pool.py", line 490, in command
    return command(self.sock, dbname, spec, slave_ok,
  File "/home/ec2-user/venv/lib64/python3.9/site-packages/pymongo/network.py", line 123, in command
    helpers._check_command_response(
  File "/home/ec2-user/venv/lib64/python3.9/site-packages/pymongo/helpers.py", line 146, in _check_command_response
    raise OperationFailure(msg % errmsg, code, response)
pymongo.errors.OperationFailure: bad auth : authentication failed
[2023-12-15 22:18:27,051] ERROR in app: Request finalizing failed with an error while handling an error
Traceback (most recent call last):
  File "/home/ec2-user/venv/lib64/python3.9/site-packages/flask/app.py", line 1455, in wsgi_app
    response = self.full_dispatch_request()
  File "/home/ec2-user/venv/lib64/python3.9/site-packages/flask/app.py", line 869, in full_dispatch_request
    rv = self.handle_user_exception(e)
  File "/home/ec2-user/venv/lib64/python3.9/site-packages/flask_cors/extension.py", line 176, in wrapped_function
    return cors_after_request(app.make_response(f(*args, **kwargs)))
  File "/home/ec2-user/venv/lib64/python3.9/site-packages/flask/app.py", line 867, in full_dispatch_request
    rv = self.dispatch_request()
  File "/home/ec2-user/venv/lib64/python3.9/site-packages/flask/app.py", line 852, in dispatch_request
    return self.ensure_sync(self.view_functions[rule.endpoint])(**view_args)
  File "/home/ec2-user/BluestPeakBackend/project/frameworks_and_drivers/controllers/product.py", line 26, in get_products
    product_dicts = interactor.execute(
  File "/home/ec2-user/BluestPeakBackend/project/use_cases/product_interactor.py", line 22, in execute
    product_dicts = self.product_dao.get_products(
  File "/home/ec2-user/BluestPeakBackend/project/interface_adapters/dao/productDao.py", line 19, in get_products
    product_list = [
  File "/home/ec2-user/BluestPeakBackend/project/interface_adapters/dao/productDao.py", line 19, in <listcomp>
    product_list = [
  File "/home/ec2-user/venv/lib64/python3.9/site-packages/pymongo/cursor.py", line 1176, in next
    if len(self.__data) or self._refresh():
  File "/home/ec2-user/venv/lib64/python3.9/site-packages/pymongo/cursor.py", line 1087, in _refresh
    self.__send_message(q)
  File "/home/ec2-user/venv/lib64/python3.9/site-packages/pymongo/cursor.py", line 923, in __send_message
    response = client._send_message_with_response(operation,
  File "/home/ec2-user/venv/lib64/python3.9/site-packages/pymongo/mongo_client.py", line 1019, in _send_message_with_response
    return self._reset_on_error(
  File "/home/ec2-user/venv/lib64/python3.9/site-packages/pymongo/mongo_client.py", line 1037, in _reset_on_error
    return func(*args, **kwargs)
  File "/home/ec2-user/venv/lib64/python3.9/site-packages/pymongo/server.py", line 85, in send_message_with_response
    with self.get_socket(all_credentials, exhaust) as sock_info:
  File "/usr/lib64/python3.9/contextlib.py", line 119, in __enter__
    return next(self.gen)
  File "/home/ec2-user/venv/lib64/python3.9/site-packages/pymongo/server.py", line 138, in get_socket
    with self.pool.get_socket(all_credentials, checkout) as sock_info:
  File "/usr/lib64/python3.9/contextlib.py", line 119, in __enter__
    return next(self.gen)
  File "/home/ec2-user/venv/lib64/python3.9/site-packages/pymongo/pool.py", line 893, in get_socket
    sock_info.check_auth(all_credentials)
  File "/home/ec2-user/venv/lib64/python3.9/site-packages/pymongo/pool.py", line 588, in check_auth
    auth.authenticate(credentials, self)
  File "/home/ec2-user/venv/lib64/python3.9/site-packages/pymongo/auth.py", line 486, in authenticate
    auth_func(credentials, sock_info)
  File "/home/ec2-user/venv/lib64/python3.9/site-packages/pymongo/auth.py", line 466, in _authenticate_default
    return _authenticate_scram_sha1(credentials, sock_info)
  File "/home/ec2-user/venv/lib64/python3.9/site-packages/pymongo/auth.py", line 237, in _authenticate_scram_sha1
    res = sock_info.command(source, cmd)
  File "/home/ec2-user/venv/lib64/python3.9/site-packages/pymongo/pool.py", line 490, in command
    return command(self.sock, dbname, spec, slave_ok,
  File "/home/ec2-user/venv/lib64/python3.9/site-packages/pymongo/network.py", line 123, in command
    helpers._check_command_response(
  File "/home/ec2-user/venv/lib64/python3.9/site-packages/pymongo/helpers.py", line 146, in _check_command_response
    raise OperationFailure(msg % errmsg, code, response)
pymongo.errors.OperationFailure: bad auth : authentication failed

During handling of the above exception, another exception occurred:

Traceback (most recent call last):
  File "/home/ec2-user/venv/lib64/python3.9/site-packages/flask/app.py", line 891, in finalize_request
    response = self.process_response(response)
  File "/home/ec2-user/venv/lib64/python3.9/site-packages/flask/app.py", line 1267, in process_response
    response = self.ensure_sync(func)(response)
  File "/home/ec2-user/BluestPeakBackend/project/frameworks_and_drivers/app.py", line 85, in after_request
    if not EnterpriseDao.enterprise_has_paid(enterprise_id):
  File "/home/ec2-user/BluestPeakBackend/project/interface_adapters/dao/enterpriseDao.py", line 64, in enterprise_has_paid
    enterprise = enterprises.find_one({'_id':enterprise_id})
  File "/home/ec2-user/venv/lib64/python3.9/site-packages/pymongo/collection.py", line 1224, in find_one
    for result in cursor.limit(-1):
  File "/home/ec2-user/venv/lib64/python3.9/site-packages/pymongo/cursor.py", line 1176, in next
    if len(self.__data) or self._refresh():
  File "/home/ec2-user/venv/lib64/python3.9/site-packages/pymongo/cursor.py", line 1087, in _refresh
    self.__send_message(q)
  File "/home/ec2-user/venv/lib64/python3.9/site-packages/pymongo/cursor.py", line 923, in __send_message
    response = client._send_message_with_response(operation,
  File "/home/ec2-user/venv/lib64/python3.9/site-packages/pymongo/mongo_client.py", line 1019, in _send_message_with_response
    return self._reset_on_error(
  File "/home/ec2-user/venv/lib64/python3.9/site-packages/pymongo/mongo_client.py", line 1037, in _reset_on_error
    return func(*args, **kwargs)
  File "/home/ec2-user/venv/lib64/python3.9/site-packages/pymongo/server.py", line 85, in send_message_with_response
    with self.get_socket(all_credentials, exhaust) as sock_info:
  File "/usr/lib64/python3.9/contextlib.py", line 119, in __enter__
    return next(self.gen)
  File "/home/ec2-user/venv/lib64/python3.9/site-packages/pymongo/server.py", line 138, in get_socket
    with self.pool.get_socket(all_credentials, checkout) as sock_info:
  File "/usr/lib64/python3.9/contextlib.py", line 119, in __enter__
    return next(self.gen)
  File "/home/ec2-user/venv/lib64/python3.9/site-packages/pymongo/pool.py", line 893, in get_socket
    sock_info.check_auth(all_credentials)
  File "/home/ec2-user/venv/lib64/python3.9/site-packages/pymongo/pool.py", line 588, in check_auth
    auth.authenticate(credentials, self)
  File "/home/ec2-user/venv/lib64/python3.9/site-packages/pymongo/auth.py", line 486, in authenticate
    auth_func(credentials, sock_info)
  File "/home/ec2-user/venv/lib64/python3.9/site-packages/pymongo/auth.py", line 466, in _authenticate_default
    return _authenticate_scram_sha1(credentials, sock_info)
  File "/home/ec2-user/venv/lib64/python3.9/site-packages/pymongo/auth.py", line 237, in _authenticate_scram_sha1
    res = sock_info.command(source, cmd)
  File "/home/ec2-user/venv/lib64/python3.9/site-packages/pymongo/pool.py", line 490, in command
    return command(self.sock, dbname, spec, slave_ok,
  File "/home/ec2-user/venv/lib64/python3.9/site-packages/pymongo/network.py", line 123, in command
    helpers._check_command_response(
  File "/home/ec2-user/venv/lib64/python3.9/site-packages/pymongo/helpers.py", line 146, in _check_command_response
    raise OperationFailure(msg % errmsg, code, response)
pymongo.errors.OperationFailure: bad auth : authentication failed
[2023-12-15 22:30:12 +0000] [139479] [INFO] Handling signal: term
[2023-12-15 22:30:12 +0000] [139480] [INFO] Worker exiting (pid: 139480)
[2023-12-15 22:30:12 +0000] [139481] [INFO] Worker exiting (pid: 139481)
[2023-12-15 22:30:12 +0000] [139482] [INFO] Worker exiting (pid: 139482)
[2023-12-15 22:30:12 +0000] [139479] [INFO] Shutting down: Master
[2023-12-15 22:30:12 +0000] [139882] [INFO] Starting gunicorn 21.2.0
[2023-12-15 22:30:12 +0000] [139882] [INFO] Listening at: http://0.0.0.0:8000 (139882)
[2023-12-15 22:30:12 +0000] [139882] [INFO] Using worker: sync
[2023-12-15 22:30:12 +0000] [139883] [INFO] Booting worker with pid: 139883
[2023-12-15 22:30:13 +0000] [139884] [INFO] Booting worker with pid: 139884
[2023-12-15 22:30:13 +0000] [139885] [INFO] Booting worker with pid: 139885
[2023-12-15 22:30:21,524] ERROR in app: Exception on /product/result [GET]
Traceback (most recent call last):
  File "/home/ec2-user/venv/lib64/python3.9/site-packages/flask/app.py", line 1455, in wsgi_app
    response = self.full_dispatch_request()
  File "/home/ec2-user/venv/lib64/python3.9/site-packages/flask/app.py", line 869, in full_dispatch_request
    rv = self.handle_user_exception(e)
  File "/home/ec2-user/venv/lib64/python3.9/site-packages/flask_cors/extension.py", line 176, in wrapped_function
    return cors_after_request(app.make_response(f(*args, **kwargs)))
  File "/home/ec2-user/venv/lib64/python3.9/site-packages/flask/app.py", line 867, in full_dispatch_request
    rv = self.dispatch_request()
  File "/home/ec2-user/venv/lib64/python3.9/site-packages/flask/app.py", line 852, in dispatch_request
    return self.ensure_sync(self.view_functions[rule.endpoint])(**view_args)
  File "/home/ec2-user/BluestPeakBackend/project/frameworks_and_drivers/controllers/product.py", line 26, in get_products
    product_dicts = interactor.execute(
  File "/home/ec2-user/BluestPeakBackend/project/use_cases/product_interactor.py", line 22, in execute
    product_dicts = self.product_dao.get_products(
  File "/home/ec2-user/BluestPeakBackend/project/interface_adapters/dao/productDao.py", line 19, in get_products
    product_list = [
  File "/home/ec2-user/BluestPeakBackend/project/interface_adapters/dao/productDao.py", line 19, in <listcomp>
    product_list = [
  File "/home/ec2-user/venv/lib64/python3.9/site-packages/pymongo/cursor.py", line 1176, in next
    if len(self.__data) or self._refresh():
  File "/home/ec2-user/venv/lib64/python3.9/site-packages/pymongo/cursor.py", line 1087, in _refresh
    self.__send_message(q)
  File "/home/ec2-user/venv/lib64/python3.9/site-packages/pymongo/cursor.py", line 923, in __send_message
    response = client._send_message_with_response(operation,
  File "/home/ec2-user/venv/lib64/python3.9/site-packages/pymongo/mongo_client.py", line 1019, in _send_message_with_response
    return self._reset_on_error(
  File "/home/ec2-user/venv/lib64/python3.9/site-packages/pymongo/mongo_client.py", line 1037, in _reset_on_error
    return func(*args, **kwargs)
  File "/home/ec2-user/venv/lib64/python3.9/site-packages/pymongo/server.py", line 85, in send_message_with_response
    with self.get_socket(all_credentials, exhaust) as sock_info:
  File "/usr/lib64/python3.9/contextlib.py", line 119, in __enter__
    return next(self.gen)
  File "/home/ec2-user/venv/lib64/python3.9/site-packages/pymongo/server.py", line 138, in get_socket
    with self.pool.get_socket(all_credentials, checkout) as sock_info:
  File "/usr/lib64/python3.9/contextlib.py", line 119, in __enter__
    return next(self.gen)
  File "/home/ec2-user/venv/lib64/python3.9/site-packages/pymongo/pool.py", line 893, in get_socket
    sock_info.check_auth(all_credentials)
  File "/home/ec2-user/venv/lib64/python3.9/site-packages/pymongo/pool.py", line 588, in check_auth
    auth.authenticate(credentials, self)
  File "/home/ec2-user/venv/lib64/python3.9/site-packages/pymongo/auth.py", line 486, in authenticate
    auth_func(credentials, sock_info)
  File "/home/ec2-user/venv/lib64/python3.9/site-packages/pymongo/auth.py", line 466, in _authenticate_default
    return _authenticate_scram_sha1(credentials, sock_info)
  File "/home/ec2-user/venv/lib64/python3.9/site-packages/pymongo/auth.py", line 237, in _authenticate_scram_sha1
    res = sock_info.command(source, cmd)
  File "/home/ec2-user/venv/lib64/python3.9/site-packages/pymongo/pool.py", line 490, in command
    return command(self.sock, dbname, spec, slave_ok,
  File "/home/ec2-user/venv/lib64/python3.9/site-packages/pymongo/network.py", line 123, in command
    helpers._check_command_response(
  File "/home/ec2-user/venv/lib64/python3.9/site-packages/pymongo/helpers.py", line 146, in _check_command_response
    raise OperationFailure(msg % errmsg, code, response)
pymongo.errors.OperationFailure: bad auth : authentication failed
[2023-12-15 22:30:21,535] ERROR in app: Request finalizing failed with an error while handling an error
Traceback (most recent call last):
  File "/home/ec2-user/venv/lib64/python3.9/site-packages/flask/app.py", line 1455, in wsgi_app
    response = self.full_dispatch_request()
  File "/home/ec2-user/venv/lib64/python3.9/site-packages/flask/app.py", line 869, in full_dispatch_request
    rv = self.handle_user_exception(e)
  File "/home/ec2-user/venv/lib64/python3.9/site-packages/flask_cors/extension.py", line 176, in wrapped_function
    return cors_after_request(app.make_response(f(*args, **kwargs)))
  File "/home/ec2-user/venv/lib64/python3.9/site-packages/flask/app.py", line 867, in full_dispatch_request
    rv = self.dispatch_request()
  File "/home/ec2-user/venv/lib64/python3.9/site-packages/flask/app.py", line 852, in dispatch_request
    return self.ensure_sync(self.view_functions[rule.endpoint])(**view_args)
  File "/home/ec2-user/BluestPeakBackend/project/frameworks_and_drivers/controllers/product.py", line 26, in get_products
    product_dicts = interactor.execute(
  File "/home/ec2-user/BluestPeakBackend/project/use_cases/product_interactor.py", line 22, in execute
    product_dicts = self.product_dao.get_products(
  File "/home/ec2-user/BluestPeakBackend/project/interface_adapters/dao/productDao.py", line 19, in get_products
    product_list = [
  File "/home/ec2-user/BluestPeakBackend/project/interface_adapters/dao/productDao.py", line 19, in <listcomp>
    product_list = [
  File "/home/ec2-user/venv/lib64/python3.9/site-packages/pymongo/cursor.py", line 1176, in next
    if len(self.__data) or self._refresh():
  File "/home/ec2-user/venv/lib64/python3.9/site-packages/pymongo/cursor.py", line 1087, in _refresh
    self.__send_message(q)
  File "/home/ec2-user/venv/lib64/python3.9/site-packages/pymongo/cursor.py", line 923, in __send_message
    response = client._send_message_with_response(operation,
  File "/home/ec2-user/venv/lib64/python3.9/site-packages/pymongo/mongo_client.py", line 1019, in _send_message_with_response
    return self._reset_on_error(
  File "/home/ec2-user/venv/lib64/python3.9/site-packages/pymongo/mongo_client.py", line 1037, in _reset_on_error
    return func(*args, **kwargs)
  File "/home/ec2-user/venv/lib64/python3.9/site-packages/pymongo/server.py", line 85, in send_message_with_response
    with self.get_socket(all_credentials, exhaust) as sock_info:
  File "/usr/lib64/python3.9/contextlib.py", line 119, in __enter__
    return next(self.gen)
  File "/home/ec2-user/venv/lib64/python3.9/site-packages/pymongo/server.py", line 138, in get_socket
    with self.pool.get_socket(all_credentials, checkout) as sock_info:
  File "/usr/lib64/python3.9/contextlib.py", line 119, in __enter__
    return next(self.gen)
  File "/home/ec2-user/venv/lib64/python3.9/site-packages/pymongo/pool.py", line 893, in get_socket
    sock_info.check_auth(all_credentials)
  File "/home/ec2-user/venv/lib64/python3.9/site-packages/pymongo/pool.py", line 588, in check_auth
    auth.authenticate(credentials, self)
  File "/home/ec2-user/venv/lib64/python3.9/site-packages/pymongo/auth.py", line 486, in authenticate
    auth_func(credentials, sock_info)
  File "/home/ec2-user/venv/lib64/python3.9/site-packages/pymongo/auth.py", line 466, in _authenticate_default
    return _authenticate_scram_sha1(credentials, sock_info)
  File "/home/ec2-user/venv/lib64/python3.9/site-packages/pymongo/auth.py", line 237, in _authenticate_scram_sha1
    res = sock_info.command(source, cmd)
  File "/home/ec2-user/venv/lib64/python3.9/site-packages/pymongo/pool.py", line 490, in command
    return command(self.sock, dbname, spec, slave_ok,
  File "/home/ec2-user/venv/lib64/python3.9/site-packages/pymongo/network.py", line 123, in command
    helpers._check_command_response(
  File "/home/ec2-user/venv/lib64/python3.9/site-packages/pymongo/helpers.py", line 146, in _check_command_response
    raise OperationFailure(msg % errmsg, code, response)
pymongo.errors.OperationFailure: bad auth : authentication failed

During handling of the above exception, another exception occurred:

Traceback (most recent call last):
  File "/home/ec2-user/venv/lib64/python3.9/site-packages/flask/app.py", line 891, in finalize_request
    response = self.process_response(response)
  File "/home/ec2-user/venv/lib64/python3.9/site-packages/flask/app.py", line 1267, in process_response
    response = self.ensure_sync(func)(response)
  File "/home/ec2-user/BluestPeakBackend/project/frameworks_and_drivers/app.py", line 85, in after_request
    if not EnterpriseDao.enterprise_has_paid(enterprise_id):
  File "/home/ec2-user/BluestPeakBackend/project/interface_adapters/dao/enterpriseDao.py", line 64, in enterprise_has_paid
    enterprise = enterprises.find_one({'_id':enterprise_id})
  File "/home/ec2-user/venv/lib64/python3.9/site-packages/pymongo/collection.py", line 1224, in find_one
    for result in cursor.limit(-1):
  File "/home/ec2-user/venv/lib64/python3.9/site-packages/pymongo/cursor.py", line 1176, in next
    if len(self.__data) or self._refresh():
  File "/home/ec2-user/venv/lib64/python3.9/site-packages/pymongo/cursor.py", line 1087, in _refresh
    self.__send_message(q)
  File "/home/ec2-user/venv/lib64/python3.9/site-packages/pymongo/cursor.py", line 923, in __send_message
    response = client._send_message_with_response(operation,
  File "/home/ec2-user/venv/lib64/python3.9/site-packages/pymongo/mongo_client.py", line 1019, in _send_message_with_response
    return self._reset_on_error(
  File "/home/ec2-user/venv/lib64/python3.9/site-packages/pymongo/mongo_client.py", line 1037, in _reset_on_error
    return func(*args, **kwargs)
  File "/home/ec2-user/venv/lib64/python3.9/site-packages/pymongo/server.py", line 85, in send_message_with_response
    with self.get_socket(all_credentials, exhaust) as sock_info:
  File "/usr/lib64/python3.9/contextlib.py", line 119, in __enter__
    return next(self.gen)
  File "/home/ec2-user/venv/lib64/python3.9/site-packages/pymongo/server.py", line 138, in get_socket
    with self.pool.get_socket(all_credentials, checkout) as sock_info:
  File "/usr/lib64/python3.9/contextlib.py", line 119, in __enter__
    return next(self.gen)
  File "/home/ec2-user/venv/lib64/python3.9/site-packages/pymongo/pool.py", line 893, in get_socket
    sock_info.check_auth(all_credentials)
  File "/home/ec2-user/venv/lib64/python3.9/site-packages/pymongo/pool.py", line 588, in check_auth
    auth.authenticate(credentials, self)
  File "/home/ec2-user/venv/lib64/python3.9/site-packages/pymongo/auth.py", line 486, in authenticate
    auth_func(credentials, sock_info)
  File "/home/ec2-user/venv/lib64/python3.9/site-packages/pymongo/auth.py", line 466, in _authenticate_default
    return _authenticate_scram_sha1(credentials, sock_info)
  File "/home/ec2-user/venv/lib64/python3.9/site-packages/pymongo/auth.py", line 237, in _authenticate_scram_sha1
    res = sock_info.command(source, cmd)
  File "/home/ec2-user/venv/lib64/python3.9/site-packages/pymongo/pool.py", line 490, in command
    return command(self.sock, dbname, spec, slave_ok,
  File "/home/ec2-user/venv/lib64/python3.9/site-packages/pymongo/network.py", line 123, in command
    helpers._check_command_response(
  File "/home/ec2-user/venv/lib64/python3.9/site-packages/pymongo/helpers.py", line 146, in _check_command_response
    raise OperationFailure(msg % errmsg, code, response)
pymongo.errors.OperationFailure: bad auth : authentication failed
[2023-12-15 22:58:36 +0000] [139883] [INFO] Worker exiting (pid: 139883)
[2023-12-15 22:58:36 +0000] [139884] [INFO] Worker exiting (pid: 139884)
[2023-12-15 22:58:36 +0000] [139885] [INFO] Worker exiting (pid: 139885)
[2023-12-15 22:58:36 +0000] [139882] [INFO] Handling signal: term
[2023-12-15 22:58:37 +0000] [139882] [INFO] Shutting down: Master
[2023-12-15 22:58:37 +0000] [140945] [INFO] Starting gunicorn 21.2.0
[2023-12-15 22:58:37 +0000] [140945] [INFO] Listening at: http://0.0.0.0:8000 (140945)
[2023-12-15 22:58:37 +0000] [140945] [INFO] Using worker: sync
[2023-12-15 22:58:37 +0000] [140947] [INFO] Booting worker with pid: 140947
[2023-12-15 22:58:37 +0000] [140948] [INFO] Booting worker with pid: 140948
[2023-12-15 22:58:37 +0000] [140949] [INFO] Booting worker with pid: 140949
[2023-12-15 22:59:09,795] ERROR in app: Exception on /product/result [GET]
Traceback (most recent call last):
  File "/home/ec2-user/venv/lib64/python3.9/site-packages/flask/app.py", line 1455, in wsgi_app
    response = self.full_dispatch_request()
  File "/home/ec2-user/venv/lib64/python3.9/site-packages/flask/app.py", line 869, in full_dispatch_request
    rv = self.handle_user_exception(e)
  File "/home/ec2-user/venv/lib64/python3.9/site-packages/flask_cors/extension.py", line 176, in wrapped_function
    return cors_after_request(app.make_response(f(*args, **kwargs)))
  File "/home/ec2-user/venv/lib64/python3.9/site-packages/flask/app.py", line 867, in full_dispatch_request
    rv = self.dispatch_request()
  File "/home/ec2-user/venv/lib64/python3.9/site-packages/flask/app.py", line 852, in dispatch_request
    return self.ensure_sync(self.view_functions[rule.endpoint])(**view_args)
  File "/home/ec2-user/BluestPeakBackend/project/frameworks_and_drivers/controllers/product.py", line 26, in get_products
    product_dicts = interactor.execute(
  File "/home/ec2-user/BluestPeakBackend/project/use_cases/product_interactor.py", line 22, in execute
    product_dicts = self.product_dao.get_products(
  File "/home/ec2-user/BluestPeakBackend/project/interface_adapters/dao/productDao.py", line 19, in get_products
    product_list = [
  File "/home/ec2-user/BluestPeakBackend/project/interface_adapters/dao/productDao.py", line 19, in <listcomp>
    product_list = [
  File "/home/ec2-user/venv/lib64/python3.9/site-packages/pymongo/cursor.py", line 1176, in next
    if len(self.__data) or self._refresh():
  File "/home/ec2-user/venv/lib64/python3.9/site-packages/pymongo/cursor.py", line 1087, in _refresh
    self.__send_message(q)
  File "/home/ec2-user/venv/lib64/python3.9/site-packages/pymongo/cursor.py", line 974, in __send_message
    helpers._check_command_response(first)
  File "/home/ec2-user/venv/lib64/python3.9/site-packages/pymongo/helpers.py", line 146, in _check_command_response
    raise OperationFailure(msg % errmsg, code, response)
pymongo.errors.OperationFailure: Unsupported OP_QUERY command: find. The client driver may require an upgrade. For more details see https://dochub.mongodb.org/core/legacy-opcode-removal
[2023-12-15 22:59:09,801] ERROR in app: Request finalizing failed with an error while handling an error
Traceback (most recent call last):
  File "/home/ec2-user/venv/lib64/python3.9/site-packages/flask/app.py", line 1455, in wsgi_app
    response = self.full_dispatch_request()
  File "/home/ec2-user/venv/lib64/python3.9/site-packages/flask/app.py", line 869, in full_dispatch_request
    rv = self.handle_user_exception(e)
  File "/home/ec2-user/venv/lib64/python3.9/site-packages/flask_cors/extension.py", line 176, in wrapped_function
    return cors_after_request(app.make_response(f(*args, **kwargs)))
  File "/home/ec2-user/venv/lib64/python3.9/site-packages/flask/app.py", line 867, in full_dispatch_request
    rv = self.dispatch_request()
  File "/home/ec2-user/venv/lib64/python3.9/site-packages/flask/app.py", line 852, in dispatch_request
    return self.ensure_sync(self.view_functions[rule.endpoint])(**view_args)
  File "/home/ec2-user/BluestPeakBackend/project/frameworks_and_drivers/controllers/product.py", line 26, in get_products
    product_dicts = interactor.execute(
  File "/home/ec2-user/BluestPeakBackend/project/use_cases/product_interactor.py", line 22, in execute
    product_dicts = self.product_dao.get_products(
  File "/home/ec2-user/BluestPeakBackend/project/interface_adapters/dao/productDao.py", line 19, in get_products
    product_list = [
  File "/home/ec2-user/BluestPeakBackend/project/interface_adapters/dao/productDao.py", line 19, in <listcomp>
    product_list = [
  File "/home/ec2-user/venv/lib64/python3.9/site-packages/pymongo/cursor.py", line 1176, in next
    if len(self.__data) or self._refresh():
  File "/home/ec2-user/venv/lib64/python3.9/site-packages/pymongo/cursor.py", line 1087, in _refresh
    self.__send_message(q)
  File "/home/ec2-user/venv/lib64/python3.9/site-packages/pymongo/cursor.py", line 974, in __send_message
    helpers._check_command_response(first)
  File "/home/ec2-user/venv/lib64/python3.9/site-packages/pymongo/helpers.py", line 146, in _check_command_response
    raise OperationFailure(msg % errmsg, code, response)
pymongo.errors.OperationFailure: Unsupported OP_QUERY command: find. The client driver may require an upgrade. For more details see https://dochub.mongodb.org/core/legacy-opcode-removal

During handling of the above exception, another exception occurred:

Traceback (most recent call last):
  File "/home/ec2-user/venv/lib64/python3.9/site-packages/flask/app.py", line 891, in finalize_request
    response = self.process_response(response)
  File "/home/ec2-user/venv/lib64/python3.9/site-packages/flask/app.py", line 1267, in process_response
    response = self.ensure_sync(func)(response)
  File "/home/ec2-user/BluestPeakBackend/project/frameworks_and_drivers/app.py", line 85, in after_request
    if not EnterpriseDao.enterprise_has_paid(enterprise_id):
  File "/home/ec2-user/BluestPeakBackend/project/interface_adapters/dao/enterpriseDao.py", line 64, in enterprise_has_paid
    enterprise = enterprises.find_one({'_id':enterprise_id})
  File "/home/ec2-user/venv/lib64/python3.9/site-packages/pymongo/collection.py", line 1224, in find_one
    for result in cursor.limit(-1):
  File "/home/ec2-user/venv/lib64/python3.9/site-packages/pymongo/cursor.py", line 1176, in next
    if len(self.__data) or self._refresh():
  File "/home/ec2-user/venv/lib64/python3.9/site-packages/pymongo/cursor.py", line 1087, in _refresh
    self.__send_message(q)
  File "/home/ec2-user/venv/lib64/python3.9/site-packages/pymongo/cursor.py", line 974, in __send_message
    helpers._check_command_response(first)
  File "/home/ec2-user/venv/lib64/python3.9/site-packages/pymongo/helpers.py", line 146, in _check_command_response
    raise OperationFailure(msg % errmsg, code, response)
pymongo.errors.OperationFailure: Unsupported OP_QUERY command: find. The client driver may require an upgrade. For more details see https://dochub.mongodb.org/core/legacy-opcode-removal
[2023-12-15 23:04:39 +0000] [140945] [INFO] Handling signal: term
[2023-12-15 23:04:39 +0000] [140947] [INFO] Worker exiting (pid: 140947)
[2023-12-15 23:04:39 +0000] [140948] [INFO] Worker exiting (pid: 140948)
[2023-12-15 23:04:39 +0000] [140949] [INFO] Worker exiting (pid: 140949)
[2023-12-15 23:04:40 +0000] [140945] [INFO] Shutting down: Master
[2023-12-15 23:04:40 +0000] [141119] [INFO] Starting gunicorn 21.2.0
[2023-12-15 23:04:40 +0000] [141119] [INFO] Listening at: http://0.0.0.0:8000 (141119)
[2023-12-15 23:04:40 +0000] [141119] [INFO] Using worker: sync
[2023-12-15 23:04:40 +0000] [141122] [INFO] Booting worker with pid: 141122
[2023-12-15 23:04:40 +0000] [141123] [INFO] Booting worker with pid: 141123
[2023-12-15 23:04:40 +0000] [141124] [INFO] Booting worker with pid: 141124
[2023-12-15 23:04:58,823] ERROR in app: Exception on /product/result [GET]
Traceback (most recent call last):
  File "/home/ec2-user/venv/lib64/python3.9/site-packages/flask/app.py", line 1455, in wsgi_app
    response = self.full_dispatch_request()
  File "/home/ec2-user/venv/lib64/python3.9/site-packages/flask/app.py", line 869, in full_dispatch_request
    rv = self.handle_user_exception(e)
  File "/home/ec2-user/venv/lib64/python3.9/site-packages/flask_cors/extension.py", line 176, in wrapped_function
    return cors_after_request(app.make_response(f(*args, **kwargs)))
  File "/home/ec2-user/venv/lib64/python3.9/site-packages/flask/app.py", line 867, in full_dispatch_request
    rv = self.dispatch_request()
  File "/home/ec2-user/venv/lib64/python3.9/site-packages/flask/app.py", line 852, in dispatch_request
    return self.ensure_sync(self.view_functions[rule.endpoint])(**view_args)
  File "/home/ec2-user/BluestPeakBackend/project/frameworks_and_drivers/controllers/product.py", line 26, in get_products
    product_dicts = interactor.execute(
  File "/home/ec2-user/BluestPeakBackend/project/use_cases/product_interactor.py", line 22, in execute
    product_dicts = self.product_dao.get_products(
  File "/home/ec2-user/BluestPeakBackend/project/interface_adapters/dao/productDao.py", line 19, in get_products
    product_list = [
  File "/home/ec2-user/BluestPeakBackend/project/interface_adapters/dao/productDao.py", line 19, in <listcomp>
    product_list = [
  File "/home/ec2-user/venv/lib64/python3.9/site-packages/pymongo/cursor.py", line 1176, in next
    if len(self.__data) or self._refresh():
  File "/home/ec2-user/venv/lib64/python3.9/site-packages/pymongo/cursor.py", line 1087, in _refresh
    self.__send_message(q)
  File "/home/ec2-user/venv/lib64/python3.9/site-packages/pymongo/cursor.py", line 974, in __send_message
    helpers._check_command_response(first)
  File "/home/ec2-user/venv/lib64/python3.9/site-packages/pymongo/helpers.py", line 146, in _check_command_response
    raise OperationFailure(msg % errmsg, code, response)
pymongo.errors.OperationFailure: Unsupported OP_QUERY command: find. The client driver may require an upgrade. For more details see https://dochub.mongodb.org/core/legacy-opcode-removal
[2023-12-15 23:04:58,826] ERROR in app: Request finalizing failed with an error while handling an error
Traceback (most recent call last):
  File "/home/ec2-user/venv/lib64/python3.9/site-packages/flask/app.py", line 1455, in wsgi_app
    response = self.full_dispatch_request()
  File "/home/ec2-user/venv/lib64/python3.9/site-packages/flask/app.py", line 869, in full_dispatch_request
    rv = self.handle_user_exception(e)
  File "/home/ec2-user/venv/lib64/python3.9/site-packages/flask_cors/extension.py", line 176, in wrapped_function
    return cors_after_request(app.make_response(f(*args, **kwargs)))
  File "/home/ec2-user/venv/lib64/python3.9/site-packages/flask/app.py", line 867, in full_dispatch_request
    rv = self.dispatch_request()
  File "/home/ec2-user/venv/lib64/python3.9/site-packages/flask/app.py", line 852, in dispatch_request
    return self.ensure_sync(self.view_functions[rule.endpoint])(**view_args)
  File "/home/ec2-user/BluestPeakBackend/project/frameworks_and_drivers/controllers/product.py", line 26, in get_products
    product_dicts = interactor.execute(
  File "/home/ec2-user/BluestPeakBackend/project/use_cases/product_interactor.py", line 22, in execute
    product_dicts = self.product_dao.get_products(
  File "/home/ec2-user/BluestPeakBackend/project/interface_adapters/dao/productDao.py", line 19, in get_products
    product_list = [
  File "/home/ec2-user/BluestPeakBackend/project/interface_adapters/dao/productDao.py", line 19, in <listcomp>
    product_list = [
  File "/home/ec2-user/venv/lib64/python3.9/site-packages/pymongo/cursor.py", line 1176, in next
    if len(self.__data) or self._refresh():
  File "/home/ec2-user/venv/lib64/python3.9/site-packages/pymongo/cursor.py", line 1087, in _refresh
    self.__send_message(q)
  File "/home/ec2-user/venv/lib64/python3.9/site-packages/pymongo/cursor.py", line 974, in __send_message
    helpers._check_command_response(first)
  File "/home/ec2-user/venv/lib64/python3.9/site-packages/pymongo/helpers.py", line 146, in _check_command_response
    raise OperationFailure(msg % errmsg, code, response)
pymongo.errors.OperationFailure: Unsupported OP_QUERY command: find. The client driver may require an upgrade. For more details see https://dochub.mongodb.org/core/legacy-opcode-removal

During handling of the above exception, another exception occurred:

Traceback (most recent call last):
  File "/home/ec2-user/venv/lib64/python3.9/site-packages/flask/app.py", line 891, in finalize_request
    response = self.process_response(response)
  File "/home/ec2-user/venv/lib64/python3.9/site-packages/flask/app.py", line 1267, in process_response
    response = self.ensure_sync(func)(response)
  File "/home/ec2-user/BluestPeakBackend/project/frameworks_and_drivers/app.py", line 85, in after_request
    if not EnterpriseDao.enterprise_has_paid(enterprise_id):
  File "/home/ec2-user/BluestPeakBackend/project/interface_adapters/dao/enterpriseDao.py", line 64, in enterprise_has_paid
    enterprise = enterprises.find_one({'_id':enterprise_id})
  File "/home/ec2-user/venv/lib64/python3.9/site-packages/pymongo/collection.py", line 1224, in find_one
    for result in cursor.limit(-1):
  File "/home/ec2-user/venv/lib64/python3.9/site-packages/pymongo/cursor.py", line 1176, in next
    if len(self.__data) or self._refresh():
  File "/home/ec2-user/venv/lib64/python3.9/site-packages/pymongo/cursor.py", line 1087, in _refresh
    self.__send_message(q)
  File "/home/ec2-user/venv/lib64/python3.9/site-packages/pymongo/cursor.py", line 974, in __send_message
    helpers._check_command_response(first)
  File "/home/ec2-user/venv/lib64/python3.9/site-packages/pymongo/helpers.py", line 146, in _check_command_response
    raise OperationFailure(msg % errmsg, code, response)
pymongo.errors.OperationFailure: Unsupported OP_QUERY command: find. The client driver may require an upgrade. For more details see https://dochub.mongodb.org/core/legacy-opcode-removal
[2023-12-15 23:10:01 +0000] [141119] [INFO] Handling signal: term
[2023-12-15 23:10:01 +0000] [141122] [INFO] Worker exiting (pid: 141122)
[2023-12-15 23:10:01 +0000] [141123] [INFO] Worker exiting (pid: 141123)
[2023-12-15 23:10:01 +0000] [141124] [INFO] Worker exiting (pid: 141124)
[2023-12-15 23:10:02 +0000] [141119] [INFO] Shutting down: Master
[2023-12-15 23:10:02 +0000] [141345] [INFO] Starting gunicorn 21.2.0
[2023-12-15 23:10:02 +0000] [141345] [INFO] Listening at: http://0.0.0.0:8000 (141345)
[2023-12-15 23:10:02 +0000] [141345] [INFO] Using worker: sync
[2023-12-15 23:10:02 +0000] [141346] [INFO] Booting worker with pid: 141346
[2023-12-15 23:10:02 +0000] [141347] [INFO] Booting worker with pid: 141347
[2023-12-15 23:10:02 +0000] [141348] [INFO] Booting worker with pid: 141348
[2023-12-15 23:10:13,225] ERROR in app: Exception on /product/result [GET]
Traceback (most recent call last):
  File "/home/ec2-user/venv/lib64/python3.9/site-packages/flask/app.py", line 1455, in wsgi_app
    response = self.full_dispatch_request()
  File "/home/ec2-user/venv/lib64/python3.9/site-packages/flask/app.py", line 869, in full_dispatch_request
    rv = self.handle_user_exception(e)
  File "/home/ec2-user/venv/lib64/python3.9/site-packages/flask_cors/extension.py", line 176, in wrapped_function
    return cors_after_request(app.make_response(f(*args, **kwargs)))
  File "/home/ec2-user/venv/lib64/python3.9/site-packages/flask/app.py", line 867, in full_dispatch_request
    rv = self.dispatch_request()
  File "/home/ec2-user/venv/lib64/python3.9/site-packages/flask/app.py", line 852, in dispatch_request
    return self.ensure_sync(self.view_functions[rule.endpoint])(**view_args)
  File "/home/ec2-user/BluestPeakBackend/project/frameworks_and_drivers/controllers/product.py", line 26, in get_products
    product_dicts = interactor.execute(
  File "/home/ec2-user/BluestPeakBackend/project/use_cases/product_interactor.py", line 22, in execute
    product_dicts = self.product_dao.get_products(
  File "/home/ec2-user/BluestPeakBackend/project/interface_adapters/dao/productDao.py", line 19, in get_products
    product_list = [
  File "/home/ec2-user/BluestPeakBackend/project/interface_adapters/dao/productDao.py", line 19, in <listcomp>
    product_list = [
  File "/home/ec2-user/venv/lib64/python3.9/site-packages/pymongo/cursor.py", line 1176, in next
    if len(self.__data) or self._refresh():
  File "/home/ec2-user/venv/lib64/python3.9/site-packages/pymongo/cursor.py", line 1087, in _refresh
    self.__send_message(q)
  File "/home/ec2-user/venv/lib64/python3.9/site-packages/pymongo/cursor.py", line 974, in __send_message
    helpers._check_command_response(first)
  File "/home/ec2-user/venv/lib64/python3.9/site-packages/pymongo/helpers.py", line 146, in _check_command_response
    raise OperationFailure(msg % errmsg, code, response)
pymongo.errors.OperationFailure: Unsupported OP_QUERY command: find. The client driver may require an upgrade. For more details see https://dochub.mongodb.org/core/legacy-opcode-removal
[2023-12-15 23:10:13,230] ERROR in app: Request finalizing failed with an error while handling an error
Traceback (most recent call last):
  File "/home/ec2-user/venv/lib64/python3.9/site-packages/flask/app.py", line 1455, in wsgi_app
    response = self.full_dispatch_request()
  File "/home/ec2-user/venv/lib64/python3.9/site-packages/flask/app.py", line 869, in full_dispatch_request
    rv = self.handle_user_exception(e)
  File "/home/ec2-user/venv/lib64/python3.9/site-packages/flask_cors/extension.py", line 176, in wrapped_function
    return cors_after_request(app.make_response(f(*args, **kwargs)))
  File "/home/ec2-user/venv/lib64/python3.9/site-packages/flask/app.py", line 867, in full_dispatch_request
    rv = self.dispatch_request()
  File "/home/ec2-user/venv/lib64/python3.9/site-packages/flask/app.py", line 852, in dispatch_request
    return self.ensure_sync(self.view_functions[rule.endpoint])(**view_args)
  File "/home/ec2-user/BluestPeakBackend/project/frameworks_and_drivers/controllers/product.py", line 26, in get_products
    product_dicts = interactor.execute(
  File "/home/ec2-user/BluestPeakBackend/project/use_cases/product_interactor.py", line 22, in execute
    product_dicts = self.product_dao.get_products(
  File "/home/ec2-user/BluestPeakBackend/project/interface_adapters/dao/productDao.py", line 19, in get_products
    product_list = [
  File "/home/ec2-user/BluestPeakBackend/project/interface_adapters/dao/productDao.py", line 19, in <listcomp>
    product_list = [
  File "/home/ec2-user/venv/lib64/python3.9/site-packages/pymongo/cursor.py", line 1176, in next
    if len(self.__data) or self._refresh():
  File "/home/ec2-user/venv/lib64/python3.9/site-packages/pymongo/cursor.py", line 1087, in _refresh
    self.__send_message(q)
  File "/home/ec2-user/venv/lib64/python3.9/site-packages/pymongo/cursor.py", line 974, in __send_message
    helpers._check_command_response(first)
  File "/home/ec2-user/venv/lib64/python3.9/site-packages/pymongo/helpers.py", line 146, in _check_command_response
    raise OperationFailure(msg % errmsg, code, response)
pymongo.errors.OperationFailure: Unsupported OP_QUERY command: find. The client driver may require an upgrade. For more details see https://dochub.mongodb.org/core/legacy-opcode-removal

During handling of the above exception, another exception occurred:

Traceback (most recent call last):
  File "/home/ec2-user/venv/lib64/python3.9/site-packages/flask/app.py", line 891, in finalize_request
    response = self.process_response(response)
  File "/home/ec2-user/venv/lib64/python3.9/site-packages/flask/app.py", line 1267, in process_response
    response = self.ensure_sync(func)(response)
  File "/home/ec2-user/BluestPeakBackend/project/frameworks_and_drivers/app.py", line 85, in after_request
    if not EnterpriseDao.enterprise_has_paid(enterprise_id):
  File "/home/ec2-user/BluestPeakBackend/project/interface_adapters/dao/enterpriseDao.py", line 64, in enterprise_has_paid
    enterprise = enterprises.find_one({'_id':enterprise_id})
  File "/home/ec2-user/venv/lib64/python3.9/site-packages/pymongo/collection.py", line 1224, in find_one
    for result in cursor.limit(-1):
  File "/home/ec2-user/venv/lib64/python3.9/site-packages/pymongo/cursor.py", line 1176, in next
    if len(self.__data) or self._refresh():
  File "/home/ec2-user/venv/lib64/python3.9/site-packages/pymongo/cursor.py", line 1087, in _refresh
    self.__send_message(q)
  File "/home/ec2-user/venv/lib64/python3.9/site-packages/pymongo/cursor.py", line 974, in __send_message
    helpers._check_command_response(first)
  File "/home/ec2-user/venv/lib64/python3.9/site-packages/pymongo/helpers.py", line 146, in _check_command_response
    raise OperationFailure(msg % errmsg, code, response)
pymongo.errors.OperationFailure: Unsupported OP_QUERY command: find. The client driver may require an upgrade. For more details see https://dochub.mongodb.org/core/legacy-opcode-removal
[2023-12-15 23:25:10 +0000] [141345] [INFO] Handling signal: term
[2023-12-15 23:25:10 +0000] [141346] [INFO] Worker exiting (pid: 141346)
[2023-12-15 23:25:10 +0000] [141347] [INFO] Worker exiting (pid: 141347)
[2023-12-15 23:25:10 +0000] [141348] [INFO] Worker exiting (pid: 141348)
[2023-12-15 23:25:10 +0000] [141345] [INFO] Shutting down: Master
[2023-12-15 23:25:11 +0000] [142245] [INFO] Starting gunicorn 21.2.0
[2023-12-15 23:25:11 +0000] [142245] [INFO] Listening at: http://0.0.0.0:8000 (142245)
[2023-12-15 23:25:11 +0000] [142245] [INFO] Using worker: sync
[2023-12-15 23:25:11 +0000] [142247] [INFO] Booting worker with pid: 142247
[2023-12-15 23:25:11 +0000] [142248] [INFO] Booting worker with pid: 142248
[2023-12-15 23:25:11 +0000] [142249] [INFO] Booting worker with pid: 142249
[2023-12-15 23:25:35,812] ERROR in app: Exception on /product/result [GET]
Traceback (most recent call last):
  File "/home/ec2-user/venv/lib64/python3.9/site-packages/flask/app.py", line 1455, in wsgi_app
    response = self.full_dispatch_request()
  File "/home/ec2-user/venv/lib64/python3.9/site-packages/flask/app.py", line 869, in full_dispatch_request
    rv = self.handle_user_exception(e)
  File "/home/ec2-user/venv/lib64/python3.9/site-packages/flask_cors/extension.py", line 176, in wrapped_function
    return cors_after_request(app.make_response(f(*args, **kwargs)))
  File "/home/ec2-user/venv/lib64/python3.9/site-packages/flask/app.py", line 867, in full_dispatch_request
    rv = self.dispatch_request()
  File "/home/ec2-user/venv/lib64/python3.9/site-packages/flask/app.py", line 852, in dispatch_request
    return self.ensure_sync(self.view_functions[rule.endpoint])(**view_args)
  File "/home/ec2-user/BluestPeakBackend/project/frameworks_and_drivers/controllers/product.py", line 26, in get_products
    product_dicts = interactor.execute(
  File "/home/ec2-user/BluestPeakBackend/project/use_cases/product_interactor.py", line 22, in execute
    product_dicts = self.product_dao.get_products(
  File "/home/ec2-user/BluestPeakBackend/project/interface_adapters/dao/productDao.py", line 19, in get_products
    product_list = [
  File "/home/ec2-user/BluestPeakBackend/project/interface_adapters/dao/productDao.py", line 19, in <listcomp>
    product_list = [
  File "/home/ec2-user/venv/lib64/python3.9/site-packages/pymongo/cursor.py", line 1176, in next
    if len(self.__data) or self._refresh():
  File "/home/ec2-user/venv/lib64/python3.9/site-packages/pymongo/cursor.py", line 1087, in _refresh
    self.__send_message(q)
  File "/home/ec2-user/venv/lib64/python3.9/site-packages/pymongo/cursor.py", line 974, in __send_message
    helpers._check_command_response(first)
  File "/home/ec2-user/venv/lib64/python3.9/site-packages/pymongo/helpers.py", line 146, in _check_command_response
    raise OperationFailure(msg % errmsg, code, response)
pymongo.errors.OperationFailure: Unsupported OP_QUERY command: find. The client driver may require an upgrade. For more details see https://dochub.mongodb.org/core/legacy-opcode-removal
[2023-12-15 23:25:35,816] ERROR in app: Request finalizing failed with an error while handling an error
Traceback (most recent call last):
  File "/home/ec2-user/venv/lib64/python3.9/site-packages/flask/app.py", line 1455, in wsgi_app
    response = self.full_dispatch_request()
  File "/home/ec2-user/venv/lib64/python3.9/site-packages/flask/app.py", line 869, in full_dispatch_request
    rv = self.handle_user_exception(e)
  File "/home/ec2-user/venv/lib64/python3.9/site-packages/flask_cors/extension.py", line 176, in wrapped_function
    return cors_after_request(app.make_response(f(*args, **kwargs)))
  File "/home/ec2-user/venv/lib64/python3.9/site-packages/flask/app.py", line 867, in full_dispatch_request
    rv = self.dispatch_request()
  File "/home/ec2-user/venv/lib64/python3.9/site-packages/flask/app.py", line 852, in dispatch_request
    return self.ensure_sync(self.view_functions[rule.endpoint])(**view_args)
  File "/home/ec2-user/BluestPeakBackend/project/frameworks_and_drivers/controllers/product.py", line 26, in get_products
    product_dicts = interactor.execute(
  File "/home/ec2-user/BluestPeakBackend/project/use_cases/product_interactor.py", line 22, in execute
    product_dicts = self.product_dao.get_products(
  File "/home/ec2-user/BluestPeakBackend/project/interface_adapters/dao/productDao.py", line 19, in get_products
    product_list = [
  File "/home/ec2-user/BluestPeakBackend/project/interface_adapters/dao/productDao.py", line 19, in <listcomp>
    product_list = [
  File "/home/ec2-user/venv/lib64/python3.9/site-packages/pymongo/cursor.py", line 1176, in next
    if len(self.__data) or self._refresh():
  File "/home/ec2-user/venv/lib64/python3.9/site-packages/pymongo/cursor.py", line 1087, in _refresh
    self.__send_message(q)
  File "/home/ec2-user/venv/lib64/python3.9/site-packages/pymongo/cursor.py", line 974, in __send_message
    helpers._check_command_response(first)
  File "/home/ec2-user/venv/lib64/python3.9/site-packages/pymongo/helpers.py", line 146, in _check_command_response
    raise OperationFailure(msg % errmsg, code, response)
pymongo.errors.OperationFailure: Unsupported OP_QUERY command: find. The client driver may require an upgrade. For more details see https://dochub.mongodb.org/core/legacy-opcode-removal

During handling of the above exception, another exception occurred:

Traceback (most recent call last):
  File "/home/ec2-user/venv/lib64/python3.9/site-packages/flask/app.py", line 891, in finalize_request
    response = self.process_response(response)
  File "/home/ec2-user/venv/lib64/python3.9/site-packages/flask/app.py", line 1267, in process_response
    response = self.ensure_sync(func)(response)
  File "/home/ec2-user/BluestPeakBackend/project/frameworks_and_drivers/app.py", line 85, in after_request
    if not EnterpriseDao.enterprise_has_paid(enterprise_id):
  File "/home/ec2-user/BluestPeakBackend/project/interface_adapters/dao/enterpriseDao.py", line 64, in enterprise_has_paid
    enterprise = enterprises.find_one({'_id':enterprise_id})
  File "/home/ec2-user/venv/lib64/python3.9/site-packages/pymongo/collection.py", line 1224, in find_one
    for result in cursor.limit(-1):
  File "/home/ec2-user/venv/lib64/python3.9/site-packages/pymongo/cursor.py", line 1176, in next
    if len(self.__data) or self._refresh():
  File "/home/ec2-user/venv/lib64/python3.9/site-packages/pymongo/cursor.py", line 1087, in _refresh
    self.__send_message(q)
  File "/home/ec2-user/venv/lib64/python3.9/site-packages/pymongo/cursor.py", line 974, in __send_message
    helpers._check_command_response(first)
  File "/home/ec2-user/venv/lib64/python3.9/site-packages/pymongo/helpers.py", line 146, in _check_command_response
    raise OperationFailure(msg % errmsg, code, response)
pymongo.errors.OperationFailure: Unsupported OP_QUERY command: find. The client driver may require an upgrade. For more details see https://dochub.mongodb.org/core/legacy-opcode-removal
[2023-12-15 23:29:40 +0000] [142245] [INFO] Handling signal: term
[2023-12-15 23:29:40 +0000] [142247] [INFO] Worker exiting (pid: 142247)
MongoDB connection string retrieved successfully
3.6.0
[2023-12-15 23:29:40 +0000] [142248] [INFO] Worker exiting (pid: 142248)
MongoDB connection string retrieved successfully
3.6.0
[2023-12-15 23:29:40 +0000] [142249] [INFO] Worker exiting (pid: 142249)
MongoDB connection string retrieved successfully
3.6.0
[2023-12-15 23:29:40 +0000] [142245] [INFO] Shutting down: Master
[2023-12-15 23:29:41 +0000] [142588] [INFO] Starting gunicorn 21.2.0
[2023-12-15 23:29:41 +0000] [142588] [INFO] Listening at: http://0.0.0.0:8000 (142588)
[2023-12-15 23:29:41 +0000] [142588] [INFO] Using worker: sync
[2023-12-15 23:29:41 +0000] [142589] [INFO] Booting worker with pid: 142589
[2023-12-15 23:29:41 +0000] [142590] [INFO] Booting worker with pid: 142590
[2023-12-15 23:29:41 +0000] [142591] [INFO] Booting worker with pid: 142591
INFO:root:PyMongo version: 3.6.0
INFO:root:PyMongo version: 3.6.0
INFO:root:PyMongo version: 3.6.0
[2023-12-15 23:33:58 +0000] [142588] [INFO] Handling signal: term
[2023-12-15 23:33:58 +0000] [142589] [INFO] Worker exiting (pid: 142589)
MongoDB connection string retrieved successfully
[2023-12-15 23:33:58 +0000] [142590] [INFO] Worker exiting (pid: 142590)
MongoDB connection string retrieved successfully
[2023-12-15 23:33:58 +0000] [142591] [INFO] Worker exiting (pid: 142591)
MongoDB connection string retrieved successfully
[2023-12-15 23:33:59 +0000] [142588] [INFO] Shutting down: Master
[2023-12-15 23:33:59 +0000] [142761] [INFO] Starting gunicorn 21.2.0
[2023-12-15 23:33:59 +0000] [142761] [INFO] Listening at: http://0.0.0.0:8000 (142761)
[2023-12-15 23:33:59 +0000] [142761] [INFO] Using worker: sync
[2023-12-15 23:33:59 +0000] [142762] [INFO] Booting worker with pid: 142762
[2023-12-15 23:33:59 +0000] [142763] [INFO] Booting worker with pid: 142763
[2023-12-15 23:33:59 +0000] [142764] [INFO] Booting worker with pid: 142764
INFO:root:PyMongo version: 4.6.1
INFO:root:PyMongo version: 4.6.1
INFO:root:PyMongo version: 4.6.1
INFO:project.frameworks_and_drivers.app:trying to get products
INFO:project.frameworks_and_drivers.app:trying to get products
[2023-12-17 23:39:11 +0000] [142761] [INFO] Handling signal: term
[2023-12-17 23:39:11 +0000] [142762] [INFO] Worker exiting (pid: 142762)
MongoDB connection string retrieved successfully
[2023-12-17 23:39:11 +0000] [142763] [INFO] Worker exiting (pid: 142763)
MongoDB connection string retrieved successfully
[2023-12-17 23:39:11 +0000] [142764] [INFO] Worker exiting (pid: 142764)
MongoDB connection string retrieved successfully
[2023-12-17 23:39:12 +0000] [142761] [INFO] Shutting down: Master
[2023-12-17 23:39:12 +0000] [214353] [INFO] Starting gunicorn 21.2.0
[2023-12-17 23:39:12 +0000] [214353] [INFO] Listening at: http://0.0.0.0:8000 (214353)
[2023-12-17 23:39:12 +0000] [214353] [INFO] Using worker: sync
[2023-12-17 23:39:12 +0000] [214355] [INFO] Booting worker with pid: 214355
[2023-12-17 23:39:12 +0000] [214356] [INFO] Booting worker with pid: 214356
[2023-12-17 23:39:12 +0000] [214357] [INFO] Booting worker with pid: 214357
INFO:root:PyMongo version: 4.6.1
INFO:root:PyMongo version: 4.6.1
INFO:root:PyMongo version: 4.6.1
INFO:project.frameworks_and_drivers.app:trying to get products
[2023-12-18 21:46:36 +0000] [214353] [INFO] Handling signal: term
[2023-12-18 21:46:36 +0000] [214355] [INFO] Worker exiting (pid: 214355)
MongoDB connection string retrieved successfully
[2023-12-18 21:46:36 +0000] [214356] [INFO] Worker exiting (pid: 214356)
MongoDB connection string retrieved successfully
[2023-12-18 21:46:36 +0000] [214357] [INFO] Worker exiting (pid: 214357)
MongoDB connection string retrieved successfully
[2023-12-18 21:46:36 +0000] [214353] [INFO] Shutting down: Master
[2023-12-18 21:46:36 +0000] [248591] [INFO] Starting gunicorn 21.2.0
[2023-12-18 21:46:36 +0000] [248591] [INFO] Listening at: http://0.0.0.0:8000 (248591)
[2023-12-18 21:46:36 +0000] [248591] [INFO] Using worker: sync
[2023-12-18 21:46:36 +0000] [248592] [INFO] Booting worker with pid: 248592
[2023-12-18 21:46:36 +0000] [248593] [INFO] Booting worker with pid: 248593
[2023-12-18 21:46:36 +0000] [248594] [INFO] Booting worker with pid: 248594
INFO:root:PyMongo version: 4.6.1
INFO:root:PyMongo version: 4.6.1
INFO:root:PyMongo version: 4.6.1
INFO:project.frameworks_and_drivers.app:trying to get users
INFO:project.frameworks_and_drivers.app:trying to get users
